[2024-10-04T14:21:26.989+0000] {taskinstance.py:1979} INFO - Dependencies all met for dep_context=non-requeueable deps ti=<TaskInstance: EL.extract manual__2024-10-04T14:21:21.520026+00:00 [queued]>
[2024-10-04T14:21:27.013+0000] {taskinstance.py:1979} INFO - Dependencies all met for dep_context=requeueable deps ti=<TaskInstance: EL.extract manual__2024-10-04T14:21:21.520026+00:00 [queued]>
[2024-10-04T14:21:27.015+0000] {taskinstance.py:2193} INFO - Starting attempt 1 of 1
[2024-10-04T14:21:27.058+0000] {taskinstance.py:2214} INFO - Executing <Task(BashOperator): extract> on 2024-10-04 14:21:21.520026+00:00
[2024-10-04T14:21:27.070+0000] {standard_task_runner.py:60} INFO - Started process 346 to run task
[2024-10-04T14:21:27.077+0000] {standard_task_runner.py:87} INFO - Running: ['airflow', 'tasks', 'run', 'EL', 'extract', 'manual__2024-10-04T14:21:21.520026+00:00', '--job-id', '3', '--raw', '--subdir', 'DAGS_FOLDER/scrape_dag.py', '--cfg-path', '/tmp/tmpm1zt2yt3']
[2024-10-04T14:21:27.082+0000] {standard_task_runner.py:88} INFO - Job 3: Subtask extract
[2024-10-04T14:21:27.125+0000] {logging_mixin.py:188} WARNING - /home/airflow/.local/lib/python3.9/site-packages/airflow/settings.py:194 DeprecationWarning: The sql_alchemy_conn option in [core] has been moved to the sql_alchemy_conn option in [database] - the old setting has been used, but please update your config.
[2024-10-04T14:21:27.224+0000] {task_command.py:423} INFO - Running <TaskInstance: EL.extract manual__2024-10-04T14:21:21.520026+00:00 [running]> on host 2d62c87db428
[2024-10-04T14:21:27.467+0000] {taskinstance.py:2510} INFO - Exporting env vars: AIRFLOW_CTX_DAG_OWNER='bmw' AIRFLOW_CTX_DAG_ID='EL' AIRFLOW_CTX_TASK_ID='extract' AIRFLOW_CTX_EXECUTION_DATE='2024-10-04T14:21:21.520026+00:00' AIRFLOW_CTX_TRY_NUMBER='1' AIRFLOW_CTX_DAG_RUN_ID='manual__2024-10-04T14:21:21.520026+00:00'
[2024-10-04T14:21:27.473+0000] {subprocess.py:63} INFO - Tmp dir root location: /tmp
[2024-10-04T14:21:27.478+0000] {subprocess.py:75} INFO - Running command: ['/usr/bin/bash', '-c', 'python3 /opt/airflow/scripts/scrape.py']
[2024-10-04T14:21:27.502+0000] {subprocess.py:86} INFO - Output:
[2024-10-04T14:31:31.517+0000] {subprocess.py:93} INFO - Traceback (most recent call last):
[2024-10-04T14:31:31.519+0000] {subprocess.py:93} INFO -   File "/opt/airflow/scripts/scrape.py", line 17, in <module>
[2024-10-04T14:31:31.523+0000] {subprocess.py:93} INFO -     driver = webdriver.Chrome(service=Service(ChromeDriverManager().install()), options=chrome_options)
[2024-10-04T14:31:31.524+0000] {subprocess.py:93} INFO -   File "/home/airflow/.local/lib/python3.9/site-packages/selenium/webdriver/chrome/webdriver.py", line 45, in __init__
[2024-10-04T14:31:31.525+0000] {subprocess.py:93} INFO -     super().__init__(
[2024-10-04T14:31:31.527+0000] {subprocess.py:93} INFO -   File "/home/airflow/.local/lib/python3.9/site-packages/selenium/webdriver/chromium/webdriver.py", line 66, in __init__
[2024-10-04T14:31:31.528+0000] {subprocess.py:93} INFO -     super().__init__(command_executor=executor, options=options)
[2024-10-04T14:31:31.530+0000] {subprocess.py:93} INFO -   File "/home/airflow/.local/lib/python3.9/site-packages/selenium/webdriver/remote/webdriver.py", line 212, in __init__
[2024-10-04T14:31:31.531+0000] {subprocess.py:93} INFO -     self.start_session(capabilities)
[2024-10-04T14:31:31.532+0000] {subprocess.py:93} INFO -   File "/home/airflow/.local/lib/python3.9/site-packages/selenium/webdriver/remote/webdriver.py", line 299, in start_session
[2024-10-04T14:31:31.534+0000] {subprocess.py:93} INFO -     response = self.execute(Command.NEW_SESSION, caps)["value"]
[2024-10-04T14:31:31.538+0000] {subprocess.py:93} INFO -   File "/home/airflow/.local/lib/python3.9/site-packages/selenium/webdriver/remote/webdriver.py", line 354, in execute
[2024-10-04T14:31:31.540+0000] {subprocess.py:93} INFO -     self.error_handler.check_response(response)
[2024-10-04T14:31:31.542+0000] {subprocess.py:93} INFO -   File "/home/airflow/.local/lib/python3.9/site-packages/selenium/webdriver/remote/errorhandler.py", line 229, in check_response
[2024-10-04T14:31:31.543+0000] {subprocess.py:93} INFO -     raise exception_class(message, screen, stacktrace)
[2024-10-04T14:31:31.545+0000] {subprocess.py:93} INFO - selenium.common.exceptions.TimeoutException: Message: timeout: Timed out receiving message from renderer: 600.000
[2024-10-04T14:31:31.546+0000] {subprocess.py:93} INFO -   (Session info: chrome=129.0.6668.89)
[2024-10-04T14:31:31.548+0000] {subprocess.py:93} INFO - Stacktrace:
[2024-10-04T14:31:31.549+0000] {subprocess.py:93} INFO - #0 0x56095434802a <unknown>
[2024-10-04T14:31:31.550+0000] {subprocess.py:93} INFO - #1 0x56095402e5e0 <unknown>
[2024-10-04T14:31:31.551+0000] {subprocess.py:93} INFO - #2 0x560954016733 <unknown>
[2024-10-04T14:31:31.552+0000] {subprocess.py:93} INFO - #3 0x560954016422 <unknown>
[2024-10-04T14:31:31.553+0000] {subprocess.py:93} INFO - #4 0x560954014493 <unknown>
[2024-10-04T14:31:31.555+0000] {subprocess.py:93} INFO - #5 0x560954014ada <unknown>
[2024-10-04T14:31:31.556+0000] {subprocess.py:93} INFO - #6 0x560954013451 <unknown>
[2024-10-04T14:31:31.557+0000] {subprocess.py:93} INFO - #7 0x56095401b9b3 <unknown>
[2024-10-04T14:31:31.559+0000] {subprocess.py:93} INFO - #8 0x56095401319b <unknown>
[2024-10-04T14:31:31.560+0000] {subprocess.py:93} INFO - #9 0x5609540160ea <unknown>
[2024-10-04T14:31:31.562+0000] {subprocess.py:93} INFO - #10 0x560954014493 <unknown>
[2024-10-04T14:31:31.563+0000] {subprocess.py:93} INFO - #11 0x560954014ada <unknown>
[2024-10-04T14:31:31.565+0000] {subprocess.py:93} INFO - #12 0x560954013451 <unknown>
[2024-10-04T14:31:31.566+0000] {subprocess.py:93} INFO - #13 0x560954009d07 <unknown>
[2024-10-04T14:31:31.568+0000] {subprocess.py:93} INFO - #14 0x56095401319b <unknown>
[2024-10-04T14:31:31.569+0000] {subprocess.py:93} INFO - #15 0x560954012aa2 <unknown>
[2024-10-04T14:31:31.571+0000] {subprocess.py:93} INFO - #16 0x560954012575 <unknown>
[2024-10-04T14:31:31.572+0000] {subprocess.py:93} INFO - #17 0x56095403080e <unknown>
[2024-10-04T14:31:31.573+0000] {subprocess.py:93} INFO - #18 0x56095400378e <unknown>
[2024-10-04T14:31:31.575+0000] {subprocess.py:93} INFO - #19 0x5609540032f6 <unknown>
[2024-10-04T14:31:31.577+0000] {subprocess.py:93} INFO - #20 0x5609540aeffc <unknown>
[2024-10-04T14:31:31.578+0000] {subprocess.py:93} INFO - #21 0x5609540ae446 <unknown>
[2024-10-04T14:31:31.579+0000] {subprocess.py:93} INFO - #22 0x5609540a28c3 <unknown>
[2024-10-04T14:31:31.580+0000] {subprocess.py:93} INFO - #23 0x5609540706b3 <unknown>
[2024-10-04T14:31:31.581+0000] {subprocess.py:93} INFO - #24 0x56095407168e <unknown>
[2024-10-04T14:31:31.582+0000] {subprocess.py:93} INFO - #25 0x560954312a2b <unknown>
[2024-10-04T14:31:31.583+0000] {subprocess.py:93} INFO - #26 0x5609543169b1 <unknown>
[2024-10-04T14:31:31.584+0000] {subprocess.py:93} INFO - #27 0x5609542ff225 <unknown>
[2024-10-04T14:31:31.586+0000] {subprocess.py:93} INFO - #28 0x560954317532 <unknown>
[2024-10-04T14:31:31.587+0000] {subprocess.py:93} INFO - #29 0x5609542e438f <unknown>
[2024-10-04T14:31:31.589+0000] {subprocess.py:93} INFO - #30 0x560954336f28 <unknown>
[2024-10-04T14:31:31.590+0000] {subprocess.py:93} INFO - #31 0x5609543370f3 <unknown>
[2024-10-04T14:31:31.592+0000] {subprocess.py:93} INFO - #32 0x560954346e7c <unknown>
[2024-10-04T14:31:31.593+0000] {subprocess.py:93} INFO - #33 0x7f05fcc73144 <unknown>
[2024-10-04T14:31:31.595+0000] {subprocess.py:93} INFO - 
[2024-10-04T14:31:31.711+0000] {subprocess.py:97} INFO - Command exited with return code 1
[2024-10-04T14:31:31.743+0000] {taskinstance.py:2728} ERROR - Task failed with exception
Traceback (most recent call last):
  File "/home/airflow/.local/lib/python3.9/site-packages/airflow/models/taskinstance.py", line 444, in _execute_task
    result = _execute_callable(context=context, **execute_callable_kwargs)
  File "/home/airflow/.local/lib/python3.9/site-packages/airflow/models/taskinstance.py", line 414, in _execute_callable
    return execute_callable(context=context, **execute_callable_kwargs)
  File "/home/airflow/.local/lib/python3.9/site-packages/airflow/operators/bash.py", line 212, in execute
    raise AirflowException(
airflow.exceptions.AirflowException: Bash command failed. The command returned a non-zero exit code 1.
[2024-10-04T14:31:31.752+0000] {taskinstance.py:1149} INFO - Marking task as FAILED. dag_id=EL, task_id=extract, execution_date=20241004T142121, start_date=20241004T142126, end_date=20241004T143131
[2024-10-04T14:31:31.785+0000] {standard_task_runner.py:107} ERROR - Failed to execute job 3 for task extract (Bash command failed. The command returned a non-zero exit code 1.; 346)
[2024-10-04T14:31:31.826+0000] {local_task_job_runner.py:234} INFO - Task exited with return code 1
[2024-10-04T14:31:31.883+0000] {taskinstance.py:3309} INFO - 0 downstream tasks scheduled from follow-on schedule check
