[2024-10-09T09:28:42.595+0000] {local_task_job_runner.py:123} INFO - ::group::Pre task execution logs
[2024-10-09T09:28:42.616+0000] {taskinstance.py:2612} INFO - Dependencies all met for dep_context=non-requeueable deps ti=<TaskInstance: EL.extract manual__2024-10-09T09:27:11.965134+00:00 [queued]>
[2024-10-09T09:28:42.627+0000] {taskinstance.py:2612} INFO - Dependencies all met for dep_context=requeueable deps ti=<TaskInstance: EL.extract manual__2024-10-09T09:27:11.965134+00:00 [queued]>
[2024-10-09T09:28:42.629+0000] {taskinstance.py:2865} INFO - Starting attempt 2 of 2
[2024-10-09T09:28:42.658+0000] {taskinstance.py:2888} INFO - Executing <Task(BashOperator): extract> on 2024-10-09 09:27:11.965134+00:00
[2024-10-09T09:28:42.672+0000] {standard_task_runner.py:72} INFO - Started process 198 to run task
[2024-10-09T09:28:42.683+0000] {standard_task_runner.py:104} INFO - Running: ['airflow', 'tasks', 'run', 'EL', 'extract', 'manual__2024-10-09T09:27:11.965134+00:00', '--job-id', '15', '--raw', '--subdir', 'DAGS_FOLDER/scrape_dag.py', '--cfg-path', '/tmp/tmpc979swzo']
[2024-10-09T09:28:42.693+0000] {standard_task_runner.py:105} INFO - Job 15: Subtask extract
[2024-10-09T09:28:42.736+0000] {warnings.py:109} WARNING - /home/airflow/.local/lib/python3.10/site-packages/airflow/settings.py:209: DeprecationWarning: The sql_alchemy_conn option in [core] has been moved to the sql_alchemy_conn option in [database] - the old setting has been used, but please update your config.
  SQL_ALCHEMY_CONN = conf.get("database", "SQL_ALCHEMY_CONN")

[2024-10-09T09:28:42.787+0000] {task_command.py:467} INFO - Running <TaskInstance: EL.extract manual__2024-10-09T09:27:11.965134+00:00 [running]> on host 6da5f868324e
[2024-10-09T09:28:42.932+0000] {taskinstance.py:3131} INFO - Exporting env vars: AIRFLOW_CTX_DAG_OWNER='bmw' AIRFLOW_CTX_DAG_ID='EL' AIRFLOW_CTX_TASK_ID='extract' AIRFLOW_CTX_EXECUTION_DATE='2024-10-09T09:27:11.965134+00:00' AIRFLOW_CTX_TRY_NUMBER='2' AIRFLOW_CTX_DAG_RUN_ID='manual__2024-10-09T09:27:11.965134+00:00'
[2024-10-09T09:28:42.934+0000] {taskinstance.py:731} INFO - ::endgroup::
[2024-10-09T09:28:42.951+0000] {subprocess.py:63} INFO - Tmp dir root location: /tmp
[2024-10-09T09:28:42.952+0000] {subprocess.py:75} INFO - Running command: ['/usr/bin/bash', '-c', 'xvfb-run --server-args="-screen 0 1920x1080x24" python3 /opt/airflow/scripts/scrape.py']
[2024-10-09T09:28:42.965+0000] {subprocess.py:86} INFO - Output:
[2024-10-09T09:28:46.091+0000] {subprocess.py:93} INFO - INFO:root:Opening IMDb page...
[2024-10-09T09:28:51.876+0000] {subprocess.py:93} INFO - INFO:root:Page loaded, waiting for elements...
[2024-10-09T09:29:52.076+0000] {subprocess.py:93} INFO - ERROR:root:Timeout: Element not found within the given time, saving screenshot...
[2024-10-09T09:29:52.357+0000] {subprocess.py:93} INFO - Traceback (most recent call last):
[2024-10-09T09:29:52.359+0000] {subprocess.py:93} INFO -   File "/opt/airflow/scripts/scrape.py", line 197, in <module>
[2024-10-09T09:29:52.362+0000] {subprocess.py:93} INFO -     WebDriverWait(driver, 60).until(
[2024-10-09T09:29:52.363+0000] {subprocess.py:93} INFO -   File "/home/airflow/.local/lib/python3.10/site-packages/selenium/webdriver/support/wait.py", line 105, in until
[2024-10-09T09:29:52.364+0000] {subprocess.py:93} INFO -     raise TimeoutException(message, screen, stacktrace)
[2024-10-09T09:29:52.365+0000] {subprocess.py:93} INFO - selenium.common.exceptions.TimeoutException: Message:
[2024-10-09T09:29:52.367+0000] {subprocess.py:93} INFO - Stacktrace:
[2024-10-09T09:29:52.368+0000] {subprocess.py:93} INFO - #0 0x55a1a072302a <unknown>
[2024-10-09T09:29:52.370+0000] {subprocess.py:93} INFO - #1 0x55a1a04095e0 <unknown>
[2024-10-09T09:29:52.371+0000] {subprocess.py:93} INFO - #2 0x55a1a0458be8 <unknown>
[2024-10-09T09:29:52.372+0000] {subprocess.py:93} INFO - #3 0x55a1a0458e81 <unknown>
[2024-10-09T09:29:52.373+0000] {subprocess.py:93} INFO - #4 0x55a1a049f8c4 <unknown>
[2024-10-09T09:29:52.375+0000] {subprocess.py:93} INFO - #5 0x55a1a047db4d <unknown>
[2024-10-09T09:29:52.376+0000] {subprocess.py:93} INFO - #6 0x55a1a049cd7d <unknown>
[2024-10-09T09:29:52.378+0000] {subprocess.py:93} INFO - #7 0x55a1a047d8c3 <unknown>
[2024-10-09T09:29:52.379+0000] {subprocess.py:93} INFO - #8 0x55a1a044b6b3 <unknown>
[2024-10-09T09:29:52.380+0000] {subprocess.py:93} INFO - #9 0x55a1a044c68e <unknown>
[2024-10-09T09:29:52.381+0000] {subprocess.py:93} INFO - #10 0x55a1a06eda2b <unknown>
[2024-10-09T09:29:52.382+0000] {subprocess.py:93} INFO - #11 0x55a1a06f19b1 <unknown>
[2024-10-09T09:29:52.383+0000] {subprocess.py:93} INFO - #12 0x55a1a06da225 <unknown>
[2024-10-09T09:29:52.384+0000] {subprocess.py:93} INFO - #13 0x55a1a06f2532 <unknown>
[2024-10-09T09:29:52.386+0000] {subprocess.py:93} INFO - #14 0x55a1a06bf38f <unknown>
[2024-10-09T09:29:52.387+0000] {subprocess.py:93} INFO - #15 0x55a1a0711f28 <unknown>
[2024-10-09T09:29:52.388+0000] {subprocess.py:93} INFO - #16 0x55a1a07120f3 <unknown>
[2024-10-09T09:29:52.389+0000] {subprocess.py:93} INFO - #17 0x55a1a0721e7c <unknown>
[2024-10-09T09:29:52.390+0000] {subprocess.py:93} INFO - #18 0x7f6bb3b4b144 <unknown>
[2024-10-09T09:29:52.392+0000] {subprocess.py:93} INFO - 
[2024-10-09T09:29:52.469+0000] {subprocess.py:97} INFO - Command exited with return code 1
[2024-10-09T09:29:52.486+0000] {taskinstance.py:3310} ERROR - Task failed with exception
Traceback (most recent call last):
  File "/home/airflow/.local/lib/python3.10/site-packages/airflow/models/taskinstance.py", line 767, in _execute_task
    result = _execute_callable(context=context, **execute_callable_kwargs)
  File "/home/airflow/.local/lib/python3.10/site-packages/airflow/models/taskinstance.py", line 733, in _execute_callable
    return ExecutionCallableRunner(
  File "/home/airflow/.local/lib/python3.10/site-packages/airflow/utils/operator_helpers.py", line 252, in run
    return self.func(*args, **kwargs)
  File "/home/airflow/.local/lib/python3.10/site-packages/airflow/models/baseoperator.py", line 406, in wrapper
    return func(self, *args, **kwargs)
  File "/home/airflow/.local/lib/python3.10/site-packages/airflow/operators/bash.py", line 249, in execute
    raise AirflowException(
airflow.exceptions.AirflowException: Bash command failed. The command returned a non-zero exit code 1.
[2024-10-09T09:29:52.493+0000] {taskinstance.py:1225} INFO - Marking task as FAILED. dag_id=EL, task_id=extract, run_id=manual__2024-10-09T09:27:11.965134+00:00, execution_date=20241009T092711, start_date=20241009T092842, end_date=20241009T092952
[2024-10-09T09:29:52.512+0000] {taskinstance.py:340} INFO - ::group::Post task execution logs
[2024-10-09T09:29:52.514+0000] {standard_task_runner.py:124} ERROR - Failed to execute job 15 for task extract (Bash command failed. The command returned a non-zero exit code 1.; 198)
Traceback (most recent call last):
  File "/home/airflow/.local/lib/python3.10/site-packages/airflow/task/task_runner/standard_task_runner.py", line 117, in _start_by_fork
    ret = args.func(args, dag=self.dag)
  File "/home/airflow/.local/lib/python3.10/site-packages/airflow/cli/cli_config.py", line 49, in command
    return func(*args, **kwargs)
  File "/home/airflow/.local/lib/python3.10/site-packages/airflow/utils/cli.py", line 115, in wrapper
    return f(*args, **kwargs)
  File "/home/airflow/.local/lib/python3.10/site-packages/airflow/cli/commands/task_command.py", line 483, in task_run
    task_return_code = _run_task_by_selected_method(args, _dag, ti)
  File "/home/airflow/.local/lib/python3.10/site-packages/airflow/cli/commands/task_command.py", line 256, in _run_task_by_selected_method
    return _run_raw_task(args, ti)
  File "/home/airflow/.local/lib/python3.10/site-packages/airflow/cli/commands/task_command.py", line 341, in _run_raw_task
    return ti._run_raw_task(
  File "/home/airflow/.local/lib/python3.10/site-packages/airflow/utils/session.py", line 97, in wrapper
    return func(*args, session=session, **kwargs)
  File "/home/airflow/.local/lib/python3.10/site-packages/airflow/models/taskinstance.py", line 3004, in _run_raw_task
    return _run_raw_task(
  File "/home/airflow/.local/lib/python3.10/site-packages/airflow/models/taskinstance.py", line 273, in _run_raw_task
    TaskInstance._execute_task_with_callbacks(
  File "/home/airflow/.local/lib/python3.10/site-packages/airflow/models/taskinstance.py", line 3158, in _execute_task_with_callbacks
    result = self._execute_task(context, task_orig)
  File "/home/airflow/.local/lib/python3.10/site-packages/airflow/models/taskinstance.py", line 3182, in _execute_task
    return _execute_task(self, context, task_orig)
  File "/home/airflow/.local/lib/python3.10/site-packages/airflow/models/taskinstance.py", line 767, in _execute_task
    result = _execute_callable(context=context, **execute_callable_kwargs)
  File "/home/airflow/.local/lib/python3.10/site-packages/airflow/models/taskinstance.py", line 733, in _execute_callable
    return ExecutionCallableRunner(
  File "/home/airflow/.local/lib/python3.10/site-packages/airflow/utils/operator_helpers.py", line 252, in run
    return self.func(*args, **kwargs)
  File "/home/airflow/.local/lib/python3.10/site-packages/airflow/models/baseoperator.py", line 406, in wrapper
    return func(self, *args, **kwargs)
  File "/home/airflow/.local/lib/python3.10/site-packages/airflow/operators/bash.py", line 249, in execute
    raise AirflowException(
airflow.exceptions.AirflowException: Bash command failed. The command returned a non-zero exit code 1.
[2024-10-09T09:29:52.554+0000] {local_task_job_runner.py:266} INFO - Task exited with return code 1
[2024-10-09T09:29:52.596+0000] {taskinstance.py:3900} INFO - 0 downstream tasks scheduled from follow-on schedule check
[2024-10-09T09:29:52.604+0000] {local_task_job_runner.py:245} INFO - ::endgroup::
