[2024-10-08T18:28:06.630+0000] {local_task_job_runner.py:123} INFO - ::group::Pre task execution logs
[2024-10-08T18:28:06.661+0000] {taskinstance.py:2612} INFO - Dependencies all met for dep_context=non-requeueable deps ti=<TaskInstance: EL.extract manual__2024-10-08T18:27:55.948816+00:00 [queued]>
[2024-10-08T18:28:06.680+0000] {taskinstance.py:2612} INFO - Dependencies all met for dep_context=requeueable deps ti=<TaskInstance: EL.extract manual__2024-10-08T18:27:55.948816+00:00 [queued]>
[2024-10-08T18:28:06.682+0000] {taskinstance.py:2865} INFO - Starting attempt 1 of 1
[2024-10-08T18:28:06.715+0000] {taskinstance.py:2888} INFO - Executing <Task(BashOperator): extract> on 2024-10-08 18:27:55.948816+00:00
[2024-10-08T18:28:06.724+0000] {standard_task_runner.py:72} INFO - Started process 52 to run task
[2024-10-08T18:28:06.733+0000] {standard_task_runner.py:104} INFO - Running: ['airflow', 'tasks', 'run', 'EL', 'extract', 'manual__2024-10-08T18:27:55.948816+00:00', '--job-id', '4', '--raw', '--subdir', 'DAGS_FOLDER/scrape_dag.py', '--cfg-path', '/tmp/tmplsnj_xa4']
[2024-10-08T18:28:06.738+0000] {standard_task_runner.py:105} INFO - Job 4: Subtask extract
[2024-10-08T18:28:06.776+0000] {warnings.py:109} WARNING - /home/airflow/.local/lib/python3.10/site-packages/airflow/settings.py:209: DeprecationWarning: The sql_alchemy_conn option in [core] has been moved to the sql_alchemy_conn option in [database] - the old setting has been used, but please update your config.
  SQL_ALCHEMY_CONN = conf.get("database", "SQL_ALCHEMY_CONN")

[2024-10-08T18:28:06.919+0000] {task_command.py:467} INFO - Running <TaskInstance: EL.extract manual__2024-10-08T18:27:55.948816+00:00 [running]> on host f3add1be504f
[2024-10-08T18:28:07.106+0000] {taskinstance.py:3131} INFO - Exporting env vars: AIRFLOW_CTX_DAG_OWNER='bmw' AIRFLOW_CTX_DAG_ID='EL' AIRFLOW_CTX_TASK_ID='extract' AIRFLOW_CTX_EXECUTION_DATE='2024-10-08T18:27:55.948816+00:00' AIRFLOW_CTX_TRY_NUMBER='1' AIRFLOW_CTX_DAG_RUN_ID='manual__2024-10-08T18:27:55.948816+00:00'
[2024-10-08T18:28:07.110+0000] {taskinstance.py:731} INFO - ::endgroup::
[2024-10-08T18:28:07.186+0000] {subprocess.py:63} INFO - Tmp dir root location: /tmp
[2024-10-08T18:28:07.189+0000] {subprocess.py:75} INFO - Running command: ['/usr/bin/bash', '-c', 'xvfb-run --server-args="-screen 0 1920x1080x24" python3 /opt/airflow/scripts/scrape.py']
[2024-10-08T18:28:07.211+0000] {subprocess.py:86} INFO - Output:
[2024-10-08T18:28:11.376+0000] {subprocess.py:93} INFO - INFO:WDM:====== WebDriver manager ======
[2024-10-08T18:28:11.655+0000] {subprocess.py:93} INFO - INFO:WDM:Get LATEST chromedriver version for google-chrome
[2024-10-08T18:28:12.043+0000] {subprocess.py:93} INFO - INFO:WDM:Get LATEST chromedriver version for google-chrome
[2024-10-08T18:28:12.143+0000] {subprocess.py:93} INFO - INFO:WDM:There is no [linux64] chromedriver "129.0.6668.89" for browser google-chrome "129.0.6668" in cache
[2024-10-08T18:28:12.146+0000] {subprocess.py:93} INFO - INFO:WDM:Get LATEST chromedriver version for google-chrome
[2024-10-08T18:28:12.398+0000] {subprocess.py:93} INFO - INFO:WDM:WebDriver version 129.0.6668.89 selected
[2024-10-08T18:28:12.403+0000] {subprocess.py:93} INFO - INFO:WDM:Modern chrome version https://storage.googleapis.com/chrome-for-testing-public/129.0.6668.89/linux64/chromedriver-linux64.zip
[2024-10-08T18:28:12.406+0000] {subprocess.py:93} INFO - INFO:WDM:About to download new driver from https://storage.googleapis.com/chrome-for-testing-public/129.0.6668.89/linux64/chromedriver-linux64.zip
[2024-10-08T18:28:12.552+0000] {subprocess.py:93} INFO - INFO:WDM:Driver downloading response is 200
[2024-10-08T18:28:16.873+0000] {subprocess.py:93} INFO - INFO:WDM:Get LATEST chromedriver version for google-chrome
[2024-10-08T18:28:17.539+0000] {subprocess.py:93} INFO - INFO:WDM:Driver has been saved in cache [/home/airflow/.wdm/drivers/chromedriver/linux64/129.0.6668.89]
[2024-10-08T18:28:19.640+0000] {subprocess.py:93} INFO - INFO:root:Opening IMDb page...
[2024-10-08T18:28:26.109+0000] {subprocess.py:93} INFO - INFO:root:Page loaded, waiting for elements...
[2024-10-08T18:28:56.535+0000] {subprocess.py:93} INFO - ERROR:root:Timeout: Element not found within the given time, saving screenshot...
[2024-10-08T18:28:58.392+0000] {subprocess.py:93} INFO - Traceback (most recent call last):
[2024-10-08T18:28:58.397+0000] {subprocess.py:93} INFO -   File "/opt/airflow/scripts/scrape.py", line 42, in <module>
[2024-10-08T18:28:58.407+0000] {subprocess.py:93} INFO -     WebDriverWait(driver, 30).until(
[2024-10-08T18:28:58.410+0000] {subprocess.py:93} INFO -   File "/home/airflow/.local/lib/python3.10/site-packages/selenium/webdriver/support/wait.py", line 105, in until
[2024-10-08T18:28:58.422+0000] {subprocess.py:93} INFO -     raise TimeoutException(message, screen, stacktrace)
[2024-10-08T18:28:58.434+0000] {subprocess.py:93} INFO - selenium.common.exceptions.TimeoutException: Message:
[2024-10-08T18:28:58.439+0000] {subprocess.py:93} INFO - Stacktrace:
[2024-10-08T18:28:58.442+0000] {subprocess.py:93} INFO - #0 0x56153788402a <unknown>
[2024-10-08T18:28:58.494+0000] {subprocess.py:93} INFO - #1 0x56153756a5e0 <unknown>
[2024-10-08T18:28:58.501+0000] {subprocess.py:93} INFO - #2 0x5615375b9be8 <unknown>
[2024-10-08T18:28:58.504+0000] {subprocess.py:93} INFO - #3 0x5615375b9e81 <unknown>
[2024-10-08T18:28:58.507+0000] {subprocess.py:93} INFO - #4 0x5615376008c4 <unknown>
[2024-10-08T18:28:58.512+0000] {subprocess.py:93} INFO - #5 0x5615375deb4d <unknown>
[2024-10-08T18:28:58.519+0000] {subprocess.py:93} INFO - #6 0x5615375fdd7d <unknown>
[2024-10-08T18:28:58.523+0000] {subprocess.py:93} INFO - #7 0x5615375de8c3 <unknown>
[2024-10-08T18:28:58.533+0000] {subprocess.py:93} INFO - #8 0x5615375ac6b3 <unknown>
[2024-10-08T18:28:58.536+0000] {subprocess.py:93} INFO - #9 0x5615375ad68e <unknown>
[2024-10-08T18:28:58.539+0000] {subprocess.py:93} INFO - #10 0x56153784ea2b <unknown>
[2024-10-08T18:28:58.558+0000] {subprocess.py:93} INFO - #11 0x5615378529b1 <unknown>
[2024-10-08T18:28:58.588+0000] {subprocess.py:93} INFO - #12 0x56153783b225 <unknown>
[2024-10-08T18:28:58.602+0000] {subprocess.py:93} INFO - #13 0x561537853532 <unknown>
[2024-10-08T18:28:58.605+0000] {subprocess.py:93} INFO - #14 0x56153782038f <unknown>
[2024-10-08T18:28:58.609+0000] {subprocess.py:93} INFO - #15 0x561537872f28 <unknown>
[2024-10-08T18:28:58.612+0000] {subprocess.py:93} INFO - #16 0x5615378730f3 <unknown>
[2024-10-08T18:28:58.618+0000] {subprocess.py:93} INFO - #17 0x561537882e7c <unknown>
[2024-10-08T18:28:58.625+0000] {subprocess.py:93} INFO - #18 0x7f7a30958144 <unknown>
[2024-10-08T18:28:58.629+0000] {subprocess.py:93} INFO - 
[2024-10-08T18:28:58.916+0000] {subprocess.py:97} INFO - Command exited with return code 1
[2024-10-08T18:28:59.018+0000] {taskinstance.py:3310} ERROR - Task failed with exception
Traceback (most recent call last):
  File "/home/airflow/.local/lib/python3.10/site-packages/airflow/models/taskinstance.py", line 767, in _execute_task
    result = _execute_callable(context=context, **execute_callable_kwargs)
  File "/home/airflow/.local/lib/python3.10/site-packages/airflow/models/taskinstance.py", line 733, in _execute_callable
    return ExecutionCallableRunner(
  File "/home/airflow/.local/lib/python3.10/site-packages/airflow/utils/operator_helpers.py", line 252, in run
    return self.func(*args, **kwargs)
  File "/home/airflow/.local/lib/python3.10/site-packages/airflow/models/baseoperator.py", line 406, in wrapper
    return func(self, *args, **kwargs)
  File "/home/airflow/.local/lib/python3.10/site-packages/airflow/operators/bash.py", line 249, in execute
    raise AirflowException(
airflow.exceptions.AirflowException: Bash command failed. The command returned a non-zero exit code 1.
[2024-10-08T18:28:59.044+0000] {taskinstance.py:1225} INFO - Marking task as FAILED. dag_id=EL, task_id=extract, run_id=manual__2024-10-08T18:27:55.948816+00:00, execution_date=20241008T182755, start_date=20241008T182806, end_date=20241008T182859
[2024-10-08T18:28:59.147+0000] {taskinstance.py:340} INFO - ::group::Post task execution logs
[2024-10-08T18:28:59.153+0000] {standard_task_runner.py:124} ERROR - Failed to execute job 4 for task extract (Bash command failed. The command returned a non-zero exit code 1.; 52)
Traceback (most recent call last):
  File "/home/airflow/.local/lib/python3.10/site-packages/airflow/task/task_runner/standard_task_runner.py", line 117, in _start_by_fork
    ret = args.func(args, dag=self.dag)
  File "/home/airflow/.local/lib/python3.10/site-packages/airflow/cli/cli_config.py", line 49, in command
    return func(*args, **kwargs)
  File "/home/airflow/.local/lib/python3.10/site-packages/airflow/utils/cli.py", line 115, in wrapper
    return f(*args, **kwargs)
  File "/home/airflow/.local/lib/python3.10/site-packages/airflow/cli/commands/task_command.py", line 483, in task_run
    task_return_code = _run_task_by_selected_method(args, _dag, ti)
  File "/home/airflow/.local/lib/python3.10/site-packages/airflow/cli/commands/task_command.py", line 256, in _run_task_by_selected_method
    return _run_raw_task(args, ti)
  File "/home/airflow/.local/lib/python3.10/site-packages/airflow/cli/commands/task_command.py", line 341, in _run_raw_task
    return ti._run_raw_task(
  File "/home/airflow/.local/lib/python3.10/site-packages/airflow/utils/session.py", line 97, in wrapper
    return func(*args, session=session, **kwargs)
  File "/home/airflow/.local/lib/python3.10/site-packages/airflow/models/taskinstance.py", line 3004, in _run_raw_task
    return _run_raw_task(
  File "/home/airflow/.local/lib/python3.10/site-packages/airflow/models/taskinstance.py", line 273, in _run_raw_task
    TaskInstance._execute_task_with_callbacks(
  File "/home/airflow/.local/lib/python3.10/site-packages/airflow/models/taskinstance.py", line 3158, in _execute_task_with_callbacks
    result = self._execute_task(context, task_orig)
  File "/home/airflow/.local/lib/python3.10/site-packages/airflow/models/taskinstance.py", line 3182, in _execute_task
    return _execute_task(self, context, task_orig)
  File "/home/airflow/.local/lib/python3.10/site-packages/airflow/models/taskinstance.py", line 767, in _execute_task
    result = _execute_callable(context=context, **execute_callable_kwargs)
  File "/home/airflow/.local/lib/python3.10/site-packages/airflow/models/taskinstance.py", line 733, in _execute_callable
    return ExecutionCallableRunner(
  File "/home/airflow/.local/lib/python3.10/site-packages/airflow/utils/operator_helpers.py", line 252, in run
    return self.func(*args, **kwargs)
  File "/home/airflow/.local/lib/python3.10/site-packages/airflow/models/baseoperator.py", line 406, in wrapper
    return func(self, *args, **kwargs)
  File "/home/airflow/.local/lib/python3.10/site-packages/airflow/operators/bash.py", line 249, in execute
    raise AirflowException(
airflow.exceptions.AirflowException: Bash command failed. The command returned a non-zero exit code 1.
[2024-10-08T18:28:59.201+0000] {local_task_job_runner.py:266} INFO - Task exited with return code 1
[2024-10-08T18:28:59.312+0000] {taskinstance.py:3900} INFO - 0 downstream tasks scheduled from follow-on schedule check
[2024-10-08T18:28:59.335+0000] {local_task_job_runner.py:245} INFO - ::endgroup::
