[2024-10-04T10:28:01.608+0000] {taskinstance.py:1979} INFO - Dependencies all met for dep_context=non-requeueable deps ti=<TaskInstance: load_imdb_data_to_bigquery.extract manual__2024-10-04T10:27:58.257859+00:00 [queued]>
[2024-10-04T10:28:01.625+0000] {taskinstance.py:1979} INFO - Dependencies all met for dep_context=requeueable deps ti=<TaskInstance: load_imdb_data_to_bigquery.extract manual__2024-10-04T10:27:58.257859+00:00 [queued]>
[2024-10-04T10:28:01.626+0000] {taskinstance.py:2193} INFO - Starting attempt 1 of 1
[2024-10-04T10:28:01.663+0000] {taskinstance.py:2214} INFO - Executing <Task(PythonOperator): extract> on 2024-10-04 10:27:58.257859+00:00
[2024-10-04T10:28:01.673+0000] {standard_task_runner.py:60} INFO - Started process 202 to run task
[2024-10-04T10:28:01.679+0000] {standard_task_runner.py:87} INFO - Running: ['airflow', 'tasks', 'run', 'load_imdb_data_to_bigquery', 'extract', 'manual__2024-10-04T10:27:58.257859+00:00', '--job-id', '3', '--raw', '--subdir', 'DAGS_FOLDER/scrape_dag.py', '--cfg-path', '/tmp/tmpprzmyx3d']
[2024-10-04T10:28:01.683+0000] {standard_task_runner.py:88} INFO - Job 3: Subtask extract
[2024-10-04T10:28:01.712+0000] {logging_mixin.py:188} WARNING - /home/airflow/.local/lib/python3.9/site-packages/airflow/settings.py:194 DeprecationWarning: The sql_alchemy_conn option in [core] has been moved to the sql_alchemy_conn option in [database] - the old setting has been used, but please update your config.
[2024-10-04T10:28:01.942+0000] {task_command.py:423} INFO - Running <TaskInstance: load_imdb_data_to_bigquery.extract manual__2024-10-04T10:27:58.257859+00:00 [running]> on host 99c1047a1b6c
[2024-10-04T10:28:02.273+0000] {taskinstance.py:2510} INFO - Exporting env vars: AIRFLOW_CTX_DAG_OWNER='bmw' AIRFLOW_CTX_DAG_ID='load_imdb_data_to_bigquery' AIRFLOW_CTX_TASK_ID='extract' AIRFLOW_CTX_EXECUTION_DATE='2024-10-04T10:27:58.257859+00:00' AIRFLOW_CTX_TRY_NUMBER='1' AIRFLOW_CTX_DAG_RUN_ID='manual__2024-10-04T10:27:58.257859+00:00'
[2024-10-04T10:28:02.288+0000] {taskinstance.py:2728} ERROR - Task failed with exception
Traceback (most recent call last):
  File "/home/airflow/.local/lib/python3.9/site-packages/airflow/models/taskinstance.py", line 444, in _execute_task
    result = _execute_callable(context=context, **execute_callable_kwargs)
  File "/home/airflow/.local/lib/python3.9/site-packages/airflow/models/taskinstance.py", line 414, in _execute_callable
    return execute_callable(context=context, **execute_callable_kwargs)
  File "/home/airflow/.local/lib/python3.9/site-packages/airflow/operators/python.py", line 200, in execute
    return_value = self.execute_callable()
  File "/home/airflow/.local/lib/python3.9/site-packages/airflow/operators/python.py", line 217, in execute_callable
    return self.python_callable(*self.op_args, **self.op_kwargs)
  File "/opt/airflow/dags/scrape_dag.py", line 61, in load_to_bigquery
    client = bigquery.Client()
  File "/home/airflow/.local/lib/python3.9/site-packages/google/cloud/bigquery/client.py", line 243, in __init__
    super(Client, self).__init__(
  File "/home/airflow/.local/lib/python3.9/site-packages/google/cloud/client/__init__.py", line 320, in __init__
    _ClientProjectMixin.__init__(self, project=project, credentials=credentials)
  File "/home/airflow/.local/lib/python3.9/site-packages/google/cloud/client/__init__.py", line 268, in __init__
    project = self._determine_default(project)
  File "/home/airflow/.local/lib/python3.9/site-packages/google/cloud/client/__init__.py", line 287, in _determine_default
    return _determine_default_project(project)
  File "/home/airflow/.local/lib/python3.9/site-packages/google/cloud/_helpers/__init__.py", line 152, in _determine_default_project
    _, project = google.auth.default()
  File "/home/airflow/.local/lib/python3.9/site-packages/google/auth/_default.py", line 659, in default
    credentials, project_id = checker()
  File "/home/airflow/.local/lib/python3.9/site-packages/google/auth/_default.py", line 652, in <lambda>
    lambda: _get_explicit_environ_credentials(quota_project_id=quota_project_id),
  File "/home/airflow/.local/lib/python3.9/site-packages/google/auth/_default.py", line 271, in _get_explicit_environ_credentials
    credentials, project_id = load_credentials_from_file(
  File "/home/airflow/.local/lib/python3.9/site-packages/google/auth/_default.py", line 114, in load_credentials_from_file
    raise exceptions.DefaultCredentialsError(
google.auth.exceptions.DefaultCredentialsError: File /gcloud_key.json was not found.
[2024-10-04T10:28:02.347+0000] {taskinstance.py:1149} INFO - Marking task as FAILED. dag_id=load_imdb_data_to_bigquery, task_id=extract, execution_date=20241004T102758, start_date=20241004T102801, end_date=20241004T102802
[2024-10-04T10:28:02.389+0000] {standard_task_runner.py:107} ERROR - Failed to execute job 3 for task extract (File /gcloud_key.json was not found.; 202)
[2024-10-04T10:28:02.416+0000] {local_task_job_runner.py:234} INFO - Task exited with return code 1
[2024-10-04T10:28:02.457+0000] {taskinstance.py:3309} INFO - 0 downstream tasks scheduled from follow-on schedule check
