[2024-10-04T16:22:54.940+0000] {taskinstance.py:1979} INFO - Dependencies all met for dep_context=non-requeueable deps ti=<TaskInstance: EL.extract manual__2024-10-04T16:22:50.826874+00:00 [queued]>
[2024-10-04T16:22:54.958+0000] {taskinstance.py:1979} INFO - Dependencies all met for dep_context=requeueable deps ti=<TaskInstance: EL.extract manual__2024-10-04T16:22:50.826874+00:00 [queued]>
[2024-10-04T16:22:54.959+0000] {taskinstance.py:2193} INFO - Starting attempt 1 of 1
[2024-10-04T16:22:54.999+0000] {taskinstance.py:2214} INFO - Executing <Task(BashOperator): extract> on 2024-10-04 16:22:50.826874+00:00
[2024-10-04T16:22:55.007+0000] {standard_task_runner.py:60} INFO - Started process 1531 to run task
[2024-10-04T16:22:55.012+0000] {standard_task_runner.py:87} INFO - Running: ['airflow', 'tasks', 'run', 'EL', 'extract', 'manual__2024-10-04T16:22:50.826874+00:00', '--job-id', '5', '--raw', '--subdir', 'DAGS_FOLDER/scrape_dag.py', '--cfg-path', '/tmp/tmp78n304rf']
[2024-10-04T16:22:55.018+0000] {standard_task_runner.py:88} INFO - Job 5: Subtask extract
[2024-10-04T16:22:55.052+0000] {logging_mixin.py:188} WARNING - /home/airflow/.local/lib/python3.9/site-packages/airflow/settings.py:194 DeprecationWarning: The sql_alchemy_conn option in [core] has been moved to the sql_alchemy_conn option in [database] - the old setting has been used, but please update your config.
[2024-10-04T16:22:55.140+0000] {task_command.py:423} INFO - Running <TaskInstance: EL.extract manual__2024-10-04T16:22:50.826874+00:00 [running]> on host 45db7544ca6a
[2024-10-04T16:22:55.303+0000] {taskinstance.py:2510} INFO - Exporting env vars: AIRFLOW_CTX_DAG_OWNER='bmw' AIRFLOW_CTX_DAG_ID='EL' AIRFLOW_CTX_TASK_ID='extract' AIRFLOW_CTX_EXECUTION_DATE='2024-10-04T16:22:50.826874+00:00' AIRFLOW_CTX_TRY_NUMBER='1' AIRFLOW_CTX_DAG_RUN_ID='manual__2024-10-04T16:22:50.826874+00:00'
[2024-10-04T16:22:55.306+0000] {subprocess.py:63} INFO - Tmp dir root location: /tmp
[2024-10-04T16:22:55.308+0000] {subprocess.py:75} INFO - Running command: ['/usr/bin/bash', '-c', 'python3 /opt/airflow/scripts/scrape.py']
[2024-10-04T16:22:55.323+0000] {subprocess.py:86} INFO - Output:
[2024-10-04T16:27:04.522+0000] {subprocess.py:93} INFO - Opening IMDb page...
[2024-10-04T16:27:04.523+0000] {subprocess.py:93} INFO - Page loaded, waiting for elements...
[2024-10-04T16:27:04.523+0000] {subprocess.py:93} INFO - Timeout: Element not found within the given time, saving screenshot...
[2024-10-04T16:27:04.524+0000] {subprocess.py:93} INFO - Traceback (most recent call last):
[2024-10-04T16:27:04.525+0000] {subprocess.py:93} INFO -   File "/opt/airflow/scripts/scrape.py", line 33, in <module>
[2024-10-04T16:27:04.525+0000] {subprocess.py:93} INFO -     WebDriverWait(driver, 240).until(
[2024-10-04T16:27:04.526+0000] {subprocess.py:93} INFO -   File "/home/airflow/.local/lib/python3.9/site-packages/selenium/webdriver/support/wait.py", line 105, in until
[2024-10-04T16:27:04.527+0000] {subprocess.py:93} INFO -     raise TimeoutException(message, screen, stacktrace)
[2024-10-04T16:27:04.527+0000] {subprocess.py:93} INFO - selenium.common.exceptions.TimeoutException: Message:
[2024-10-04T16:27:04.528+0000] {subprocess.py:93} INFO - Stacktrace:
[2024-10-04T16:27:04.528+0000] {subprocess.py:93} INFO - #0 0x55ede683602a <unknown>
[2024-10-04T16:27:04.529+0000] {subprocess.py:93} INFO - #1 0x55ede651c5e0 <unknown>
[2024-10-04T16:27:04.530+0000] {subprocess.py:93} INFO - #2 0x55ede656bbe8 <unknown>
[2024-10-04T16:27:04.530+0000] {subprocess.py:93} INFO - #3 0x55ede656be81 <unknown>
[2024-10-04T16:27:04.531+0000] {subprocess.py:93} INFO - #4 0x55ede65b28c4 <unknown>
[2024-10-04T16:27:04.531+0000] {subprocess.py:93} INFO - #5 0x55ede6590b4d <unknown>
[2024-10-04T16:27:04.531+0000] {subprocess.py:93} INFO - #6 0x55ede65afd7d <unknown>
[2024-10-04T16:27:04.532+0000] {subprocess.py:93} INFO - #7 0x55ede65908c3 <unknown>
[2024-10-04T16:27:04.532+0000] {subprocess.py:93} INFO - #8 0x55ede655e6b3 <unknown>
[2024-10-04T16:27:04.532+0000] {subprocess.py:93} INFO - #9 0x55ede655f68e <unknown>
[2024-10-04T16:27:04.533+0000] {subprocess.py:93} INFO - #10 0x55ede6800a2b <unknown>
[2024-10-04T16:27:04.533+0000] {subprocess.py:93} INFO - #11 0x55ede68049b1 <unknown>
[2024-10-04T16:27:04.534+0000] {subprocess.py:93} INFO - #12 0x55ede67ed225 <unknown>
[2024-10-04T16:27:04.534+0000] {subprocess.py:93} INFO - #13 0x55ede6805532 <unknown>
[2024-10-04T16:27:04.534+0000] {subprocess.py:93} INFO - #14 0x55ede67d238f <unknown>
[2024-10-04T16:27:04.535+0000] {subprocess.py:93} INFO - #15 0x55ede6824f28 <unknown>
[2024-10-04T16:27:04.535+0000] {subprocess.py:93} INFO - #16 0x55ede68250f3 <unknown>
[2024-10-04T16:27:04.535+0000] {subprocess.py:93} INFO - #17 0x55ede6834e7c <unknown>
[2024-10-04T16:27:04.536+0000] {subprocess.py:93} INFO - #18 0x7fdaa6a3c144 <unknown>
[2024-10-04T16:27:04.536+0000] {subprocess.py:93} INFO - 
[2024-10-04T16:27:04.617+0000] {subprocess.py:97} INFO - Command exited with return code 1
[2024-10-04T16:27:04.631+0000] {taskinstance.py:2728} ERROR - Task failed with exception
Traceback (most recent call last):
  File "/home/airflow/.local/lib/python3.9/site-packages/airflow/models/taskinstance.py", line 444, in _execute_task
    result = _execute_callable(context=context, **execute_callable_kwargs)
  File "/home/airflow/.local/lib/python3.9/site-packages/airflow/models/taskinstance.py", line 414, in _execute_callable
    return execute_callable(context=context, **execute_callable_kwargs)
  File "/home/airflow/.local/lib/python3.9/site-packages/airflow/operators/bash.py", line 212, in execute
    raise AirflowException(
airflow.exceptions.AirflowException: Bash command failed. The command returned a non-zero exit code 1.
[2024-10-04T16:27:04.635+0000] {taskinstance.py:1149} INFO - Marking task as FAILED. dag_id=EL, task_id=extract, execution_date=20241004T162250, start_date=20241004T162254, end_date=20241004T162704
[2024-10-04T16:27:04.663+0000] {standard_task_runner.py:107} ERROR - Failed to execute job 5 for task extract (Bash command failed. The command returned a non-zero exit code 1.; 1531)
[2024-10-04T16:27:04.713+0000] {local_task_job_runner.py:234} INFO - Task exited with return code 1
[2024-10-04T16:27:04.744+0000] {taskinstance.py:3309} INFO - 0 downstream tasks scheduled from follow-on schedule check
