[2024-10-04T17:01:41.581+0000] {taskinstance.py:1979} INFO - Dependencies all met for dep_context=non-requeueable deps ti=<TaskInstance: EL.extract manual__2024-10-04T16:42:28.150493+00:00 [queued]>
[2024-10-04T17:01:41.632+0000] {taskinstance.py:1979} INFO - Dependencies all met for dep_context=requeueable deps ti=<TaskInstance: EL.extract manual__2024-10-04T16:42:28.150493+00:00 [queued]>
[2024-10-04T17:01:41.635+0000] {taskinstance.py:2193} INFO - Starting attempt 2 of 2
[2024-10-04T17:01:41.730+0000] {taskinstance.py:2214} INFO - Executing <Task(BashOperator): extract> on 2024-10-04 16:42:28.150493+00:00
[2024-10-04T17:01:41.750+0000] {standard_task_runner.py:60} INFO - Started process 1301 to run task
[2024-10-04T17:01:41.767+0000] {standard_task_runner.py:87} INFO - Running: ['airflow', 'tasks', 'run', 'EL', 'extract', 'manual__2024-10-04T16:42:28.150493+00:00', '--job-id', '4', '--raw', '--subdir', 'DAGS_FOLDER/scrape_dag.py', '--cfg-path', '/tmp/tmp_81hgds4']
[2024-10-04T17:01:41.778+0000] {standard_task_runner.py:88} INFO - Job 4: Subtask extract
[2024-10-04T17:01:41.850+0000] {logging_mixin.py:188} WARNING - /home/airflow/.local/lib/python3.9/site-packages/airflow/settings.py:194 DeprecationWarning: The sql_alchemy_conn option in [core] has been moved to the sql_alchemy_conn option in [database] - the old setting has been used, but please update your config.
[2024-10-04T17:01:41.986+0000] {task_command.py:423} INFO - Running <TaskInstance: EL.extract manual__2024-10-04T16:42:28.150493+00:00 [running]> on host 04464e4fcbe1
[2024-10-04T17:01:42.287+0000] {taskinstance.py:2510} INFO - Exporting env vars: AIRFLOW_CTX_DAG_OWNER='bmw' AIRFLOW_CTX_DAG_ID='EL' AIRFLOW_CTX_TASK_ID='extract' AIRFLOW_CTX_EXECUTION_DATE='2024-10-04T16:42:28.150493+00:00' AIRFLOW_CTX_TRY_NUMBER='2' AIRFLOW_CTX_DAG_RUN_ID='manual__2024-10-04T16:42:28.150493+00:00'
[2024-10-04T17:01:42.293+0000] {subprocess.py:63} INFO - Tmp dir root location: /tmp
[2024-10-04T17:01:42.297+0000] {subprocess.py:75} INFO - Running command: ['/usr/bin/bash', '-c', 'python3 /opt/airflow/scripts/scrape.py']
[2024-10-04T17:01:42.322+0000] {subprocess.py:86} INFO - Output:
[2024-10-04T17:01:45.097+0000] {subprocess.py:93} INFO - INFO:WDM:====== WebDriver manager ======
[2024-10-04T17:01:45.329+0000] {subprocess.py:93} INFO - INFO:WDM:Get LATEST chromedriver version for google-chrome
[2024-10-04T17:01:45.562+0000] {subprocess.py:93} INFO - INFO:WDM:Get LATEST chromedriver version for google-chrome
[2024-10-04T17:01:45.716+0000] {subprocess.py:93} INFO - INFO:WDM:Driver [/home/airflow/.wdm/drivers/chromedriver/linux64/129.0.6668.89/chromedriver] found in cache
[2024-10-04T17:01:47.171+0000] {subprocess.py:93} INFO - INFO:root:Opening IMDb page...
[2024-10-04T17:01:52.765+0000] {subprocess.py:93} INFO - INFO:root:Page loaded, waiting for elements...
[2024-10-04T17:02:22.864+0000] {subprocess.py:93} INFO - ERROR:root:Timeout: Element not found within the given time, saving screenshot...
[2024-10-04T17:02:23.762+0000] {subprocess.py:93} INFO - Traceback (most recent call last):
[2024-10-04T17:02:23.764+0000] {subprocess.py:93} INFO -   File "/opt/airflow/scripts/scrape.py", line 42, in <module>
[2024-10-04T17:02:23.770+0000] {subprocess.py:93} INFO -     WebDriverWait(driver, 30).until(
[2024-10-04T17:02:23.773+0000] {subprocess.py:93} INFO -   File "/home/airflow/.local/lib/python3.9/site-packages/selenium/webdriver/support/wait.py", line 105, in until
[2024-10-04T17:02:23.774+0000] {subprocess.py:93} INFO -     raise TimeoutException(message, screen, stacktrace)
[2024-10-04T17:02:23.775+0000] {subprocess.py:93} INFO - selenium.common.exceptions.TimeoutException: Message:
[2024-10-04T17:02:23.777+0000] {subprocess.py:93} INFO - Stacktrace:
[2024-10-04T17:02:23.778+0000] {subprocess.py:93} INFO - #0 0x56349de8502a <unknown>
[2024-10-04T17:02:23.779+0000] {subprocess.py:93} INFO - #1 0x56349db6b5e0 <unknown>
[2024-10-04T17:02:23.780+0000] {subprocess.py:93} INFO - #2 0x56349dbbabe8 <unknown>
[2024-10-04T17:02:23.782+0000] {subprocess.py:93} INFO - #3 0x56349dbbae81 <unknown>
[2024-10-04T17:02:23.783+0000] {subprocess.py:93} INFO - #4 0x56349dc018c4 <unknown>
[2024-10-04T17:02:23.784+0000] {subprocess.py:93} INFO - #5 0x56349dbdfb4d <unknown>
[2024-10-04T17:02:23.786+0000] {subprocess.py:93} INFO - #6 0x56349dbfed7d <unknown>
[2024-10-04T17:02:23.787+0000] {subprocess.py:93} INFO - #7 0x56349dbdf8c3 <unknown>
[2024-10-04T17:02:23.789+0000] {subprocess.py:93} INFO - #8 0x56349dbad6b3 <unknown>
[2024-10-04T17:02:23.790+0000] {subprocess.py:93} INFO - #9 0x56349dbae68e <unknown>
[2024-10-04T17:02:23.791+0000] {subprocess.py:93} INFO - #10 0x56349de4fa2b <unknown>
[2024-10-04T17:02:23.793+0000] {subprocess.py:93} INFO - #11 0x56349de539b1 <unknown>
[2024-10-04T17:02:23.794+0000] {subprocess.py:93} INFO - #12 0x56349de3c225 <unknown>
[2024-10-04T17:02:23.796+0000] {subprocess.py:93} INFO - #13 0x56349de54532 <unknown>
[2024-10-04T17:02:23.797+0000] {subprocess.py:93} INFO - #14 0x56349de2138f <unknown>
[2024-10-04T17:02:23.800+0000] {subprocess.py:93} INFO - #15 0x56349de73f28 <unknown>
[2024-10-04T17:02:23.804+0000] {subprocess.py:93} INFO - #16 0x56349de740f3 <unknown>
[2024-10-04T17:02:23.811+0000] {subprocess.py:93} INFO - #17 0x56349de83e7c <unknown>
[2024-10-04T17:02:23.813+0000] {subprocess.py:93} INFO - #18 0x7fb663141144 <unknown>
[2024-10-04T17:02:23.815+0000] {subprocess.py:93} INFO - 
[2024-10-04T17:02:24.050+0000] {subprocess.py:97} INFO - Command exited with return code 1
[2024-10-04T17:02:24.112+0000] {taskinstance.py:2728} ERROR - Task failed with exception
Traceback (most recent call last):
  File "/home/airflow/.local/lib/python3.9/site-packages/airflow/models/taskinstance.py", line 444, in _execute_task
    result = _execute_callable(context=context, **execute_callable_kwargs)
  File "/home/airflow/.local/lib/python3.9/site-packages/airflow/models/taskinstance.py", line 414, in _execute_callable
    return execute_callable(context=context, **execute_callable_kwargs)
  File "/home/airflow/.local/lib/python3.9/site-packages/airflow/operators/bash.py", line 212, in execute
    raise AirflowException(
airflow.exceptions.AirflowException: Bash command failed. The command returned a non-zero exit code 1.
[2024-10-04T17:02:24.153+0000] {taskinstance.py:1149} INFO - Marking task as FAILED. dag_id=EL, task_id=extract, execution_date=20241004T164228, start_date=20241004T170141, end_date=20241004T170224
[2024-10-04T17:02:24.224+0000] {standard_task_runner.py:107} ERROR - Failed to execute job 4 for task extract (Bash command failed. The command returned a non-zero exit code 1.; 1301)
[2024-10-04T17:02:24.287+0000] {local_task_job_runner.py:234} INFO - Task exited with return code 1
[2024-10-04T17:02:24.396+0000] {taskinstance.py:3309} INFO - 0 downstream tasks scheduled from follow-on schedule check
