[2024-10-04T16:42:32.642+0000] {taskinstance.py:1979} INFO - Dependencies all met for dep_context=non-requeueable deps ti=<TaskInstance: EL.extract manual__2024-10-04T16:42:28.150493+00:00 [queued]>
[2024-10-04T16:42:32.657+0000] {taskinstance.py:1979} INFO - Dependencies all met for dep_context=requeueable deps ti=<TaskInstance: EL.extract manual__2024-10-04T16:42:28.150493+00:00 [queued]>
[2024-10-04T16:42:32.659+0000] {taskinstance.py:2193} INFO - Starting attempt 1 of 1
[2024-10-04T16:42:32.693+0000] {taskinstance.py:2214} INFO - Executing <Task(BashOperator): extract> on 2024-10-04 16:42:28.150493+00:00
[2024-10-04T16:42:32.701+0000] {standard_task_runner.py:60} INFO - Started process 222 to run task
[2024-10-04T16:42:32.706+0000] {standard_task_runner.py:87} INFO - Running: ['airflow', 'tasks', 'run', 'EL', 'extract', 'manual__2024-10-04T16:42:28.150493+00:00', '--job-id', '3', '--raw', '--subdir', 'DAGS_FOLDER/scrape_dag.py', '--cfg-path', '/tmp/tmpl_cfdt0x']
[2024-10-04T16:42:32.709+0000] {standard_task_runner.py:88} INFO - Job 3: Subtask extract
[2024-10-04T16:42:32.738+0000] {logging_mixin.py:188} WARNING - /home/airflow/.local/lib/python3.9/site-packages/airflow/settings.py:194 DeprecationWarning: The sql_alchemy_conn option in [core] has been moved to the sql_alchemy_conn option in [database] - the old setting has been used, but please update your config.
[2024-10-04T16:42:32.797+0000] {task_command.py:423} INFO - Running <TaskInstance: EL.extract manual__2024-10-04T16:42:28.150493+00:00 [running]> on host 04464e4fcbe1
[2024-10-04T16:42:32.941+0000] {taskinstance.py:2510} INFO - Exporting env vars: AIRFLOW_CTX_DAG_OWNER='bmw' AIRFLOW_CTX_DAG_ID='EL' AIRFLOW_CTX_TASK_ID='extract' AIRFLOW_CTX_EXECUTION_DATE='2024-10-04T16:42:28.150493+00:00' AIRFLOW_CTX_TRY_NUMBER='1' AIRFLOW_CTX_DAG_RUN_ID='manual__2024-10-04T16:42:28.150493+00:00'
[2024-10-04T16:42:32.944+0000] {subprocess.py:63} INFO - Tmp dir root location: /tmp
[2024-10-04T16:42:32.946+0000] {subprocess.py:75} INFO - Running command: ['/usr/bin/bash', '-c', 'python3 /opt/airflow/scripts/scrape.py']
[2024-10-04T16:42:32.960+0000] {subprocess.py:86} INFO - Output:
[2024-10-04T16:52:49.523+0000] {subprocess.py:93} INFO - Opening IMDb page...
[2024-10-04T16:52:49.523+0000] {subprocess.py:93} INFO - Page loaded, waiting for elements...
[2024-10-04T16:52:49.524+0000] {subprocess.py:93} INFO - Timeout: Element not found within the given time, saving screenshot...
[2024-10-04T16:52:49.525+0000] {subprocess.py:93} INFO - Traceback (most recent call last):
[2024-10-04T16:52:49.525+0000] {subprocess.py:93} INFO -   File "/opt/airflow/scripts/scrape.py", line 33, in <module>
[2024-10-04T16:52:49.526+0000] {subprocess.py:93} INFO -     WebDriverWait(driver, 600).until(
[2024-10-04T16:52:49.526+0000] {subprocess.py:93} INFO -   File "/home/airflow/.local/lib/python3.9/site-packages/selenium/webdriver/support/wait.py", line 105, in until
[2024-10-04T16:52:49.527+0000] {subprocess.py:93} INFO -     raise TimeoutException(message, screen, stacktrace)
[2024-10-04T16:52:49.527+0000] {subprocess.py:93} INFO - selenium.common.exceptions.TimeoutException: Message:
[2024-10-04T16:52:49.528+0000] {subprocess.py:93} INFO - Stacktrace:
[2024-10-04T16:52:49.528+0000] {subprocess.py:93} INFO - #0 0x560dcb21a02a <unknown>
[2024-10-04T16:52:49.529+0000] {subprocess.py:93} INFO - #1 0x560dcaf005e0 <unknown>
[2024-10-04T16:52:49.529+0000] {subprocess.py:93} INFO - #2 0x560dcaf4fbe8 <unknown>
[2024-10-04T16:52:49.530+0000] {subprocess.py:93} INFO - #3 0x560dcaf4fe81 <unknown>
[2024-10-04T16:52:49.530+0000] {subprocess.py:93} INFO - #4 0x560dcaf968c4 <unknown>
[2024-10-04T16:52:49.531+0000] {subprocess.py:93} INFO - #5 0x560dcaf74b4d <unknown>
[2024-10-04T16:52:49.531+0000] {subprocess.py:93} INFO - #6 0x560dcaf93d7d <unknown>
[2024-10-04T16:52:49.531+0000] {subprocess.py:93} INFO - #7 0x560dcaf748c3 <unknown>
[2024-10-04T16:52:49.532+0000] {subprocess.py:93} INFO - #8 0x560dcaf426b3 <unknown>
[2024-10-04T16:52:49.532+0000] {subprocess.py:93} INFO - #9 0x560dcaf4368e <unknown>
[2024-10-04T16:52:49.533+0000] {subprocess.py:93} INFO - #10 0x560dcb1e4a2b <unknown>
[2024-10-04T16:52:49.533+0000] {subprocess.py:93} INFO - #11 0x560dcb1e89b1 <unknown>
[2024-10-04T16:52:49.534+0000] {subprocess.py:93} INFO - #12 0x560dcb1d1225 <unknown>
[2024-10-04T16:52:49.535+0000] {subprocess.py:93} INFO - #13 0x560dcb1e9532 <unknown>
[2024-10-04T16:52:49.535+0000] {subprocess.py:93} INFO - #14 0x560dcb1b638f <unknown>
[2024-10-04T16:52:49.536+0000] {subprocess.py:93} INFO - #15 0x560dcb208f28 <unknown>
[2024-10-04T16:52:49.536+0000] {subprocess.py:93} INFO - #16 0x560dcb2090f3 <unknown>
[2024-10-04T16:52:49.537+0000] {subprocess.py:93} INFO - #17 0x560dcb218e7c <unknown>
[2024-10-04T16:52:49.537+0000] {subprocess.py:93} INFO - #18 0x7f67cc9ab144 <unknown>
[2024-10-04T16:52:49.538+0000] {subprocess.py:93} INFO - 
[2024-10-04T16:52:49.620+0000] {subprocess.py:97} INFO - Command exited with return code 1
[2024-10-04T16:52:49.633+0000] {taskinstance.py:2728} ERROR - Task failed with exception
Traceback (most recent call last):
  File "/home/airflow/.local/lib/python3.9/site-packages/airflow/models/taskinstance.py", line 444, in _execute_task
    result = _execute_callable(context=context, **execute_callable_kwargs)
  File "/home/airflow/.local/lib/python3.9/site-packages/airflow/models/taskinstance.py", line 414, in _execute_callable
    return execute_callable(context=context, **execute_callable_kwargs)
  File "/home/airflow/.local/lib/python3.9/site-packages/airflow/operators/bash.py", line 212, in execute
    raise AirflowException(
airflow.exceptions.AirflowException: Bash command failed. The command returned a non-zero exit code 1.
[2024-10-04T16:52:49.638+0000] {taskinstance.py:1149} INFO - Marking task as FAILED. dag_id=EL, task_id=extract, execution_date=20241004T164228, start_date=20241004T164232, end_date=20241004T165249
[2024-10-04T16:52:49.656+0000] {standard_task_runner.py:107} ERROR - Failed to execute job 3 for task extract (Bash command failed. The command returned a non-zero exit code 1.; 222)
[2024-10-04T16:52:49.671+0000] {local_task_job_runner.py:234} INFO - Task exited with return code 1
[2024-10-04T16:52:49.696+0000] {taskinstance.py:3309} INFO - 0 downstream tasks scheduled from follow-on schedule check
