[2024-10-09T09:40:55.687+0000] {local_task_job_runner.py:123} INFO - ::group::Pre task execution logs
[2024-10-09T09:40:55.718+0000] {taskinstance.py:2612} INFO - Dependencies all met for dep_context=non-requeueable deps ti=<TaskInstance: EL.load manual__2024-10-09T09:40:18.654481+00:00 [queued]>
[2024-10-09T09:40:55.735+0000] {taskinstance.py:2612} INFO - Dependencies all met for dep_context=requeueable deps ti=<TaskInstance: EL.load manual__2024-10-09T09:40:18.654481+00:00 [queued]>
[2024-10-09T09:40:55.737+0000] {taskinstance.py:2865} INFO - Starting attempt 1 of 1
[2024-10-09T09:40:55.772+0000] {taskinstance.py:2888} INFO - Executing <Task(PythonOperator): load> on 2024-10-09 09:40:18.654481+00:00
[2024-10-09T09:40:55.784+0000] {standard_task_runner.py:72} INFO - Started process 874 to run task
[2024-10-09T09:40:55.789+0000] {standard_task_runner.py:104} INFO - Running: ['airflow', 'tasks', 'run', 'EL', 'load', 'manual__2024-10-09T09:40:18.654481+00:00', '--job-id', '18', '--raw', '--subdir', 'DAGS_FOLDER/scrape_dag.py', '--cfg-path', '/tmp/tmpniuhybck']
[2024-10-09T09:40:55.795+0000] {standard_task_runner.py:105} INFO - Job 18: Subtask load
[2024-10-09T09:40:55.819+0000] {warnings.py:109} WARNING - /home/airflow/.local/lib/python3.10/site-packages/airflow/settings.py:209: DeprecationWarning: The sql_alchemy_conn option in [core] has been moved to the sql_alchemy_conn option in [database] - the old setting has been used, but please update your config.
  SQL_ALCHEMY_CONN = conf.get("database", "SQL_ALCHEMY_CONN")

[2024-10-09T09:40:55.883+0000] {task_command.py:467} INFO - Running <TaskInstance: EL.load manual__2024-10-09T09:40:18.654481+00:00 [running]> on host 6da5f868324e
[2024-10-09T09:40:56.050+0000] {taskinstance.py:3131} INFO - Exporting env vars: AIRFLOW_CTX_DAG_OWNER='bmw' AIRFLOW_CTX_DAG_ID='EL' AIRFLOW_CTX_TASK_ID='load' AIRFLOW_CTX_EXECUTION_DATE='2024-10-09T09:40:18.654481+00:00' AIRFLOW_CTX_TRY_NUMBER='1' AIRFLOW_CTX_DAG_RUN_ID='manual__2024-10-09T09:40:18.654481+00:00'
[2024-10-09T09:40:56.054+0000] {taskinstance.py:731} INFO - ::endgroup::
[2024-10-09T09:40:56.089+0000] {taskinstance.py:3310} ERROR - Task failed with exception
Traceback (most recent call last):
  File "/home/airflow/.local/lib/python3.10/site-packages/airflow/models/taskinstance.py", line 767, in _execute_task
    result = _execute_callable(context=context, **execute_callable_kwargs)
  File "/home/airflow/.local/lib/python3.10/site-packages/airflow/models/taskinstance.py", line 733, in _execute_callable
    return ExecutionCallableRunner(
  File "/home/airflow/.local/lib/python3.10/site-packages/airflow/utils/operator_helpers.py", line 252, in run
    return self.func(*args, **kwargs)
  File "/home/airflow/.local/lib/python3.10/site-packages/airflow/models/baseoperator.py", line 406, in wrapper
    return func(self, *args, **kwargs)
  File "/home/airflow/.local/lib/python3.10/site-packages/airflow/operators/python.py", line 238, in execute
    return_value = self.execute_callable()
  File "/home/airflow/.local/lib/python3.10/site-packages/airflow/operators/python.py", line 256, in execute_callable
    return runner.run(*self.op_args, **self.op_kwargs)
  File "/home/airflow/.local/lib/python3.10/site-packages/airflow/utils/operator_helpers.py", line 252, in run
    return self.func(*args, **kwargs)
  File "/opt/airflow/dags/scrape_dag.py", line 27, in load_to_bigquery
    client = bigquery.Client()
  File "/home/airflow/.local/lib/python3.10/site-packages/google/cloud/bigquery/client.py", line 241, in __init__
    super(Client, self).__init__(
  File "/home/airflow/.local/lib/python3.10/site-packages/google/cloud/client/__init__.py", line 320, in __init__
    _ClientProjectMixin.__init__(self, project=project, credentials=credentials)
  File "/home/airflow/.local/lib/python3.10/site-packages/google/cloud/client/__init__.py", line 268, in __init__
    project = self._determine_default(project)
  File "/home/airflow/.local/lib/python3.10/site-packages/google/cloud/client/__init__.py", line 287, in _determine_default
    return _determine_default_project(project)
  File "/home/airflow/.local/lib/python3.10/site-packages/google/cloud/_helpers/__init__.py", line 152, in _determine_default_project
    _, project = google.auth.default()
  File "/home/airflow/.local/lib/python3.10/site-packages/google/auth/_default.py", line 657, in default
    credentials, project_id = checker()
  File "/home/airflow/.local/lib/python3.10/site-packages/google/auth/_default.py", line 650, in <lambda>
    lambda: _get_explicit_environ_credentials(quota_project_id=quota_project_id),
  File "/home/airflow/.local/lib/python3.10/site-packages/google/auth/_default.py", line 270, in _get_explicit_environ_credentials
    credentials, project_id = load_credentials_from_file(
  File "/home/airflow/.local/lib/python3.10/site-packages/google/auth/_default.py", line 114, in load_credentials_from_file
    raise exceptions.DefaultCredentialsError(
google.auth.exceptions.DefaultCredentialsError: File /opt/airflow/gcloud_key.json was not found.
[2024-10-09T09:40:56.118+0000] {taskinstance.py:1225} INFO - Marking task as FAILED. dag_id=EL, task_id=load, run_id=manual__2024-10-09T09:40:18.654481+00:00, execution_date=20241009T094018, start_date=20241009T094055, end_date=20241009T094056
[2024-10-09T09:40:56.148+0000] {taskinstance.py:340} INFO - ::group::Post task execution logs
[2024-10-09T09:40:56.152+0000] {standard_task_runner.py:124} ERROR - Failed to execute job 18 for task load (File /opt/airflow/gcloud_key.json was not found.; 874)
Traceback (most recent call last):
  File "/home/airflow/.local/lib/python3.10/site-packages/airflow/task/task_runner/standard_task_runner.py", line 117, in _start_by_fork
    ret = args.func(args, dag=self.dag)
  File "/home/airflow/.local/lib/python3.10/site-packages/airflow/cli/cli_config.py", line 49, in command
    return func(*args, **kwargs)
  File "/home/airflow/.local/lib/python3.10/site-packages/airflow/utils/cli.py", line 115, in wrapper
    return f(*args, **kwargs)
  File "/home/airflow/.local/lib/python3.10/site-packages/airflow/cli/commands/task_command.py", line 483, in task_run
    task_return_code = _run_task_by_selected_method(args, _dag, ti)
  File "/home/airflow/.local/lib/python3.10/site-packages/airflow/cli/commands/task_command.py", line 256, in _run_task_by_selected_method
    return _run_raw_task(args, ti)
  File "/home/airflow/.local/lib/python3.10/site-packages/airflow/cli/commands/task_command.py", line 341, in _run_raw_task
    return ti._run_raw_task(
  File "/home/airflow/.local/lib/python3.10/site-packages/airflow/utils/session.py", line 97, in wrapper
    return func(*args, session=session, **kwargs)
  File "/home/airflow/.local/lib/python3.10/site-packages/airflow/models/taskinstance.py", line 3004, in _run_raw_task
    return _run_raw_task(
  File "/home/airflow/.local/lib/python3.10/site-packages/airflow/models/taskinstance.py", line 273, in _run_raw_task
    TaskInstance._execute_task_with_callbacks(
  File "/home/airflow/.local/lib/python3.10/site-packages/airflow/models/taskinstance.py", line 3158, in _execute_task_with_callbacks
    result = self._execute_task(context, task_orig)
  File "/home/airflow/.local/lib/python3.10/site-packages/airflow/models/taskinstance.py", line 3182, in _execute_task
    return _execute_task(self, context, task_orig)
  File "/home/airflow/.local/lib/python3.10/site-packages/airflow/models/taskinstance.py", line 767, in _execute_task
    result = _execute_callable(context=context, **execute_callable_kwargs)
  File "/home/airflow/.local/lib/python3.10/site-packages/airflow/models/taskinstance.py", line 733, in _execute_callable
    return ExecutionCallableRunner(
  File "/home/airflow/.local/lib/python3.10/site-packages/airflow/utils/operator_helpers.py", line 252, in run
    return self.func(*args, **kwargs)
  File "/home/airflow/.local/lib/python3.10/site-packages/airflow/models/baseoperator.py", line 406, in wrapper
    return func(self, *args, **kwargs)
  File "/home/airflow/.local/lib/python3.10/site-packages/airflow/operators/python.py", line 238, in execute
    return_value = self.execute_callable()
  File "/home/airflow/.local/lib/python3.10/site-packages/airflow/operators/python.py", line 256, in execute_callable
    return runner.run(*self.op_args, **self.op_kwargs)
  File "/home/airflow/.local/lib/python3.10/site-packages/airflow/utils/operator_helpers.py", line 252, in run
    return self.func(*args, **kwargs)
  File "/opt/airflow/dags/scrape_dag.py", line 27, in load_to_bigquery
    client = bigquery.Client()
  File "/home/airflow/.local/lib/python3.10/site-packages/google/cloud/bigquery/client.py", line 241, in __init__
    super(Client, self).__init__(
  File "/home/airflow/.local/lib/python3.10/site-packages/google/cloud/client/__init__.py", line 320, in __init__
    _ClientProjectMixin.__init__(self, project=project, credentials=credentials)
  File "/home/airflow/.local/lib/python3.10/site-packages/google/cloud/client/__init__.py", line 268, in __init__
    project = self._determine_default(project)
  File "/home/airflow/.local/lib/python3.10/site-packages/google/cloud/client/__init__.py", line 287, in _determine_default
    return _determine_default_project(project)
  File "/home/airflow/.local/lib/python3.10/site-packages/google/cloud/_helpers/__init__.py", line 152, in _determine_default_project
    _, project = google.auth.default()
  File "/home/airflow/.local/lib/python3.10/site-packages/google/auth/_default.py", line 657, in default
    credentials, project_id = checker()
  File "/home/airflow/.local/lib/python3.10/site-packages/google/auth/_default.py", line 650, in <lambda>
    lambda: _get_explicit_environ_credentials(quota_project_id=quota_project_id),
  File "/home/airflow/.local/lib/python3.10/site-packages/google/auth/_default.py", line 270, in _get_explicit_environ_credentials
    credentials, project_id = load_credentials_from_file(
  File "/home/airflow/.local/lib/python3.10/site-packages/google/auth/_default.py", line 114, in load_credentials_from_file
    raise exceptions.DefaultCredentialsError(
google.auth.exceptions.DefaultCredentialsError: File /opt/airflow/gcloud_key.json was not found.
[2024-10-09T09:40:56.208+0000] {local_task_job_runner.py:266} INFO - Task exited with return code 1
[2024-10-09T09:40:56.244+0000] {taskinstance.py:3900} INFO - 0 downstream tasks scheduled from follow-on schedule check
[2024-10-09T09:40:56.259+0000] {local_task_job_runner.py:245} INFO - ::endgroup::
