[2024-10-04T14:09:27.359+0000] {taskinstance.py:1979} INFO - Dependencies all met for dep_context=non-requeueable deps ti=<TaskInstance: EL.extract manual__2024-10-04T14:09:22.814267+00:00 [queued]>
[2024-10-04T14:09:27.387+0000] {taskinstance.py:1979} INFO - Dependencies all met for dep_context=requeueable deps ti=<TaskInstance: EL.extract manual__2024-10-04T14:09:22.814267+00:00 [queued]>
[2024-10-04T14:09:27.388+0000] {taskinstance.py:2193} INFO - Starting attempt 1 of 1
[2024-10-04T14:09:27.437+0000] {taskinstance.py:2214} INFO - Executing <Task(BashOperator): extract> on 2024-10-04 14:09:22.814267+00:00
[2024-10-04T14:09:27.447+0000] {standard_task_runner.py:60} INFO - Started process 221 to run task
[2024-10-04T14:09:27.455+0000] {standard_task_runner.py:87} INFO - Running: ['airflow', 'tasks', 'run', 'EL', 'extract', 'manual__2024-10-04T14:09:22.814267+00:00', '--job-id', '3', '--raw', '--subdir', 'DAGS_FOLDER/scrape_dag.py', '--cfg-path', '/tmp/tmpza3l5cni']
[2024-10-04T14:09:27.459+0000] {standard_task_runner.py:88} INFO - Job 3: Subtask extract
[2024-10-04T14:09:27.508+0000] {logging_mixin.py:188} WARNING - /home/airflow/.local/lib/python3.9/site-packages/airflow/settings.py:194 DeprecationWarning: The sql_alchemy_conn option in [core] has been moved to the sql_alchemy_conn option in [database] - the old setting has been used, but please update your config.
[2024-10-04T14:09:27.619+0000] {task_command.py:423} INFO - Running <TaskInstance: EL.extract manual__2024-10-04T14:09:22.814267+00:00 [running]> on host 983f3aa1a1d1
[2024-10-04T14:09:27.834+0000] {taskinstance.py:2510} INFO - Exporting env vars: AIRFLOW_CTX_DAG_OWNER='bmw' AIRFLOW_CTX_DAG_ID='EL' AIRFLOW_CTX_TASK_ID='extract' AIRFLOW_CTX_EXECUTION_DATE='2024-10-04T14:09:22.814267+00:00' AIRFLOW_CTX_TRY_NUMBER='1' AIRFLOW_CTX_DAG_RUN_ID='manual__2024-10-04T14:09:22.814267+00:00'
[2024-10-04T14:09:27.838+0000] {subprocess.py:63} INFO - Tmp dir root location: /tmp
[2024-10-04T14:09:27.840+0000] {subprocess.py:75} INFO - Running command: ['/usr/bin/bash', '-c', 'python3 /opt/airflow/scripts/scrape.py']
[2024-10-04T14:09:27.864+0000] {subprocess.py:86} INFO - Output:
[2024-10-04T14:19:39.389+0000] {subprocess.py:93} INFO - Traceback (most recent call last):
[2024-10-04T14:19:39.391+0000] {subprocess.py:93} INFO -   File "/opt/airflow/scripts/scrape.py", line 17, in <module>
[2024-10-04T14:19:39.395+0000] {subprocess.py:93} INFO -     driver = webdriver.Chrome(service=Service(ChromeDriverManager().install()), options=chrome_options)
[2024-10-04T14:19:39.397+0000] {subprocess.py:93} INFO -   File "/home/airflow/.local/lib/python3.9/site-packages/selenium/webdriver/chrome/webdriver.py", line 45, in __init__
[2024-10-04T14:19:39.398+0000] {subprocess.py:93} INFO -     super().__init__(
[2024-10-04T14:19:39.399+0000] {subprocess.py:93} INFO -   File "/home/airflow/.local/lib/python3.9/site-packages/selenium/webdriver/chromium/webdriver.py", line 66, in __init__
[2024-10-04T14:19:39.401+0000] {subprocess.py:93} INFO -     super().__init__(command_executor=executor, options=options)
[2024-10-04T14:19:39.402+0000] {subprocess.py:93} INFO -   File "/home/airflow/.local/lib/python3.9/site-packages/selenium/webdriver/remote/webdriver.py", line 212, in __init__
[2024-10-04T14:19:39.403+0000] {subprocess.py:93} INFO -     self.start_session(capabilities)
[2024-10-04T14:19:39.404+0000] {subprocess.py:93} INFO -   File "/home/airflow/.local/lib/python3.9/site-packages/selenium/webdriver/remote/webdriver.py", line 299, in start_session
[2024-10-04T14:19:39.406+0000] {subprocess.py:93} INFO -     response = self.execute(Command.NEW_SESSION, caps)["value"]
[2024-10-04T14:19:39.407+0000] {subprocess.py:93} INFO -   File "/home/airflow/.local/lib/python3.9/site-packages/selenium/webdriver/remote/webdriver.py", line 354, in execute
[2024-10-04T14:19:39.408+0000] {subprocess.py:93} INFO -     self.error_handler.check_response(response)
[2024-10-04T14:19:39.409+0000] {subprocess.py:93} INFO -   File "/home/airflow/.local/lib/python3.9/site-packages/selenium/webdriver/remote/errorhandler.py", line 229, in check_response
[2024-10-04T14:19:39.410+0000] {subprocess.py:93} INFO -     raise exception_class(message, screen, stacktrace)
[2024-10-04T14:19:39.412+0000] {subprocess.py:93} INFO - selenium.common.exceptions.TimeoutException: Message: timeout: Timed out receiving message from renderer: 600.000
[2024-10-04T14:19:39.413+0000] {subprocess.py:93} INFO -   (Session info: chrome=129.0.6668.89)
[2024-10-04T14:19:39.414+0000] {subprocess.py:93} INFO - Stacktrace:
[2024-10-04T14:19:39.415+0000] {subprocess.py:93} INFO - #0 0x56356d3d802a <unknown>
[2024-10-04T14:19:39.416+0000] {subprocess.py:93} INFO - #1 0x56356d0be5e0 <unknown>
[2024-10-04T14:19:39.418+0000] {subprocess.py:93} INFO - #2 0x56356d0a6733 <unknown>
[2024-10-04T14:19:39.419+0000] {subprocess.py:93} INFO - #3 0x56356d0a6422 <unknown>
[2024-10-04T14:19:39.420+0000] {subprocess.py:93} INFO - #4 0x56356d0a4493 <unknown>
[2024-10-04T14:19:39.421+0000] {subprocess.py:93} INFO - #5 0x56356d0a4ada <unknown>
[2024-10-04T14:19:39.422+0000] {subprocess.py:93} INFO - #6 0x56356d0a3451 <unknown>
[2024-10-04T14:19:39.424+0000] {subprocess.py:93} INFO - #7 0x56356d0ab9b3 <unknown>
[2024-10-04T14:19:39.425+0000] {subprocess.py:93} INFO - #8 0x56356d0a319b <unknown>
[2024-10-04T14:19:39.426+0000] {subprocess.py:93} INFO - #9 0x56356d0a60ea <unknown>
[2024-10-04T14:19:39.428+0000] {subprocess.py:93} INFO - #10 0x56356d0a4493 <unknown>
[2024-10-04T14:19:39.429+0000] {subprocess.py:93} INFO - #11 0x56356d0a4ada <unknown>
[2024-10-04T14:19:39.430+0000] {subprocess.py:93} INFO - #12 0x56356d0a3451 <unknown>
[2024-10-04T14:19:39.431+0000] {subprocess.py:93} INFO - #13 0x56356d099d07 <unknown>
[2024-10-04T14:19:39.432+0000] {subprocess.py:93} INFO - #14 0x56356d0a319b <unknown>
[2024-10-04T14:19:39.435+0000] {subprocess.py:93} INFO - #15 0x56356d0a2aa2 <unknown>
[2024-10-04T14:19:39.436+0000] {subprocess.py:93} INFO - #16 0x56356d0a2575 <unknown>
[2024-10-04T14:19:39.437+0000] {subprocess.py:93} INFO - #17 0x56356d0c080e <unknown>
[2024-10-04T14:19:39.439+0000] {subprocess.py:93} INFO - #18 0x56356d09378e <unknown>
[2024-10-04T14:19:39.440+0000] {subprocess.py:93} INFO - #19 0x56356d0932f6 <unknown>
[2024-10-04T14:19:39.441+0000] {subprocess.py:93} INFO - #20 0x56356d13effc <unknown>
[2024-10-04T14:19:39.442+0000] {subprocess.py:93} INFO - #21 0x56356d13e446 <unknown>
[2024-10-04T14:19:39.444+0000] {subprocess.py:93} INFO - #22 0x56356d1328c3 <unknown>
[2024-10-04T14:19:39.445+0000] {subprocess.py:93} INFO - #23 0x56356d1006b3 <unknown>
[2024-10-04T14:19:39.446+0000] {subprocess.py:93} INFO - #24 0x56356d10168e <unknown>
[2024-10-04T14:19:39.448+0000] {subprocess.py:93} INFO - #25 0x56356d3a2a2b <unknown>
[2024-10-04T14:19:39.449+0000] {subprocess.py:93} INFO - #26 0x56356d3a69b1 <unknown>
[2024-10-04T14:19:39.450+0000] {subprocess.py:93} INFO - #27 0x56356d38f225 <unknown>
[2024-10-04T14:19:39.452+0000] {subprocess.py:93} INFO - #28 0x56356d3a7532 <unknown>
[2024-10-04T14:19:39.453+0000] {subprocess.py:93} INFO - #29 0x56356d37438f <unknown>
[2024-10-04T14:19:39.454+0000] {subprocess.py:93} INFO - #30 0x56356d3c6f28 <unknown>
[2024-10-04T14:19:39.455+0000] {subprocess.py:93} INFO - #31 0x56356d3c70f3 <unknown>
[2024-10-04T14:19:39.457+0000] {subprocess.py:93} INFO - #32 0x56356d3d6e7c <unknown>
[2024-10-04T14:19:39.458+0000] {subprocess.py:93} INFO - #33 0x7f5411444144 <unknown>
[2024-10-04T14:19:39.459+0000] {subprocess.py:93} INFO - 
[2024-10-04T14:19:39.558+0000] {subprocess.py:97} INFO - Command exited with return code 1
[2024-10-04T14:19:39.590+0000] {taskinstance.py:2728} ERROR - Task failed with exception
Traceback (most recent call last):
  File "/home/airflow/.local/lib/python3.9/site-packages/airflow/models/taskinstance.py", line 444, in _execute_task
    result = _execute_callable(context=context, **execute_callable_kwargs)
  File "/home/airflow/.local/lib/python3.9/site-packages/airflow/models/taskinstance.py", line 414, in _execute_callable
    return execute_callable(context=context, **execute_callable_kwargs)
  File "/home/airflow/.local/lib/python3.9/site-packages/airflow/operators/bash.py", line 212, in execute
    raise AirflowException(
airflow.exceptions.AirflowException: Bash command failed. The command returned a non-zero exit code 1.
[2024-10-04T14:19:39.599+0000] {taskinstance.py:1149} INFO - Marking task as FAILED. dag_id=EL, task_id=extract, execution_date=20241004T140922, start_date=20241004T140927, end_date=20241004T141939
[2024-10-04T14:19:39.646+0000] {standard_task_runner.py:107} ERROR - Failed to execute job 3 for task extract (Bash command failed. The command returned a non-zero exit code 1.; 221)
[2024-10-04T14:19:39.662+0000] {local_task_job_runner.py:234} INFO - Task exited with return code 1
[2024-10-04T14:19:39.709+0000] {taskinstance.py:3309} INFO - 0 downstream tasks scheduled from follow-on schedule check
