[2024-10-09T09:31:43.995+0000] {local_task_job_runner.py:123} INFO - ::group::Pre task execution logs
[2024-10-09T09:31:44.040+0000] {taskinstance.py:2612} INFO - Dependencies all met for dep_context=non-requeueable deps ti=<TaskInstance: EL.extract manual__2024-10-09T09:31:42.177124+00:00 [queued]>
[2024-10-09T09:31:44.064+0000] {taskinstance.py:2612} INFO - Dependencies all met for dep_context=requeueable deps ti=<TaskInstance: EL.extract manual__2024-10-09T09:31:42.177124+00:00 [queued]>
[2024-10-09T09:31:44.067+0000] {taskinstance.py:2865} INFO - Starting attempt 1 of 1
[2024-10-09T09:31:44.104+0000] {taskinstance.py:2888} INFO - Executing <Task(BashOperator): extract> on 2024-10-09 09:31:42.177124+00:00
[2024-10-09T09:31:44.112+0000] {standard_task_runner.py:72} INFO - Started process 432 to run task
[2024-10-09T09:31:44.120+0000] {standard_task_runner.py:104} INFO - Running: ['airflow', 'tasks', 'run', 'EL', 'extract', 'manual__2024-10-09T09:31:42.177124+00:00', '--job-id', '16', '--raw', '--subdir', 'DAGS_FOLDER/scrape_dag.py', '--cfg-path', '/tmp/tmpn7feft9o']
[2024-10-09T09:31:44.127+0000] {standard_task_runner.py:105} INFO - Job 16: Subtask extract
[2024-10-09T09:31:44.155+0000] {warnings.py:109} WARNING - /home/airflow/.local/lib/python3.10/site-packages/airflow/settings.py:209: DeprecationWarning: The sql_alchemy_conn option in [core] has been moved to the sql_alchemy_conn option in [database] - the old setting has been used, but please update your config.
  SQL_ALCHEMY_CONN = conf.get("database", "SQL_ALCHEMY_CONN")

[2024-10-09T09:31:44.222+0000] {task_command.py:467} INFO - Running <TaskInstance: EL.extract manual__2024-10-09T09:31:42.177124+00:00 [running]> on host 6da5f868324e
[2024-10-09T09:31:44.341+0000] {taskinstance.py:3131} INFO - Exporting env vars: AIRFLOW_CTX_DAG_OWNER='bmw' AIRFLOW_CTX_DAG_ID='EL' AIRFLOW_CTX_TASK_ID='extract' AIRFLOW_CTX_EXECUTION_DATE='2024-10-09T09:31:42.177124+00:00' AIRFLOW_CTX_TRY_NUMBER='1' AIRFLOW_CTX_DAG_RUN_ID='manual__2024-10-09T09:31:42.177124+00:00'
[2024-10-09T09:31:44.345+0000] {taskinstance.py:731} INFO - ::endgroup::
[2024-10-09T09:31:44.373+0000] {subprocess.py:63} INFO - Tmp dir root location: /tmp
[2024-10-09T09:31:44.375+0000] {subprocess.py:75} INFO - Running command: ['/usr/bin/bash', '-c', 'xvfb-run --server-args="-screen 0 1920x1080x24" python3 /opt/airflow/scripts/scrape.py']
[2024-10-09T09:31:44.389+0000] {subprocess.py:86} INFO - Output:
[2024-10-09T09:31:46.662+0000] {subprocess.py:93} INFO - INFO:root:Opening IMDb page...
[2024-10-09T09:31:52.244+0000] {subprocess.py:93} INFO - INFO:root:Page loaded, waiting for elements...
[2024-10-09T09:32:52.702+0000] {subprocess.py:93} INFO - ERROR:root:Timeout: Element not found within the given time, saving screenshot...
[2024-10-09T09:32:52.902+0000] {subprocess.py:93} INFO - Traceback (most recent call last):
[2024-10-09T09:32:52.904+0000] {subprocess.py:93} INFO -   File "/opt/airflow/scripts/scrape.py", line 200, in <module>
[2024-10-09T09:32:52.907+0000] {subprocess.py:93} INFO -     WebDriverWait(driver, 60).until(
[2024-10-09T09:32:52.908+0000] {subprocess.py:93} INFO -   File "/home/airflow/.local/lib/python3.10/site-packages/selenium/webdriver/support/wait.py", line 105, in until
[2024-10-09T09:32:52.910+0000] {subprocess.py:93} INFO -     raise TimeoutException(message, screen, stacktrace)
[2024-10-09T09:32:52.911+0000] {subprocess.py:93} INFO - selenium.common.exceptions.TimeoutException: Message:
[2024-10-09T09:32:52.912+0000] {subprocess.py:93} INFO - Stacktrace:
[2024-10-09T09:32:52.914+0000] {subprocess.py:93} INFO - #0 0x555fadfd602a <unknown>
[2024-10-09T09:32:52.915+0000] {subprocess.py:93} INFO - #1 0x555fadcbc5e0 <unknown>
[2024-10-09T09:32:52.916+0000] {subprocess.py:93} INFO - #2 0x555fadd0bbe8 <unknown>
[2024-10-09T09:32:52.917+0000] {subprocess.py:93} INFO - #3 0x555fadd0be81 <unknown>
[2024-10-09T09:32:52.919+0000] {subprocess.py:93} INFO - #4 0x555fadd528c4 <unknown>
[2024-10-09T09:32:52.920+0000] {subprocess.py:93} INFO - #5 0x555fadd30b4d <unknown>
[2024-10-09T09:32:52.922+0000] {subprocess.py:93} INFO - #6 0x555fadd4fd7d <unknown>
[2024-10-09T09:32:52.923+0000] {subprocess.py:93} INFO - #7 0x555fadd308c3 <unknown>
[2024-10-09T09:32:52.925+0000] {subprocess.py:93} INFO - #8 0x555fadcfe6b3 <unknown>
[2024-10-09T09:32:52.926+0000] {subprocess.py:93} INFO - #9 0x555fadcff68e <unknown>
[2024-10-09T09:32:52.928+0000] {subprocess.py:93} INFO - #10 0x555fadfa0a2b <unknown>
[2024-10-09T09:32:52.930+0000] {subprocess.py:93} INFO - #11 0x555fadfa49b1 <unknown>
[2024-10-09T09:32:52.931+0000] {subprocess.py:93} INFO - #12 0x555fadf8d225 <unknown>
[2024-10-09T09:32:52.932+0000] {subprocess.py:93} INFO - #13 0x555fadfa5532 <unknown>
[2024-10-09T09:32:52.934+0000] {subprocess.py:93} INFO - #14 0x555fadf7238f <unknown>
[2024-10-09T09:32:52.935+0000] {subprocess.py:93} INFO - #15 0x555fadfc4f28 <unknown>
[2024-10-09T09:32:52.937+0000] {subprocess.py:93} INFO - #16 0x555fadfc50f3 <unknown>
[2024-10-09T09:32:52.938+0000] {subprocess.py:93} INFO - #17 0x555fadfd4e7c <unknown>
[2024-10-09T09:32:52.940+0000] {subprocess.py:93} INFO - #18 0x7f6efc3a9144 <unknown>
[2024-10-09T09:32:52.941+0000] {subprocess.py:93} INFO - 
[2024-10-09T09:32:53.013+0000] {subprocess.py:97} INFO - Command exited with return code 1
[2024-10-09T09:32:53.031+0000] {taskinstance.py:3310} ERROR - Task failed with exception
Traceback (most recent call last):
  File "/home/airflow/.local/lib/python3.10/site-packages/airflow/models/taskinstance.py", line 767, in _execute_task
    result = _execute_callable(context=context, **execute_callable_kwargs)
  File "/home/airflow/.local/lib/python3.10/site-packages/airflow/models/taskinstance.py", line 733, in _execute_callable
    return ExecutionCallableRunner(
  File "/home/airflow/.local/lib/python3.10/site-packages/airflow/utils/operator_helpers.py", line 252, in run
    return self.func(*args, **kwargs)
  File "/home/airflow/.local/lib/python3.10/site-packages/airflow/models/baseoperator.py", line 406, in wrapper
    return func(self, *args, **kwargs)
  File "/home/airflow/.local/lib/python3.10/site-packages/airflow/operators/bash.py", line 249, in execute
    raise AirflowException(
airflow.exceptions.AirflowException: Bash command failed. The command returned a non-zero exit code 1.
[2024-10-09T09:32:53.036+0000] {taskinstance.py:1225} INFO - Marking task as FAILED. dag_id=EL, task_id=extract, run_id=manual__2024-10-09T09:31:42.177124+00:00, execution_date=20241009T093142, start_date=20241009T093144, end_date=20241009T093253
[2024-10-09T09:32:53.056+0000] {taskinstance.py:340} INFO - ::group::Post task execution logs
[2024-10-09T09:32:53.058+0000] {standard_task_runner.py:124} ERROR - Failed to execute job 16 for task extract (Bash command failed. The command returned a non-zero exit code 1.; 432)
Traceback (most recent call last):
  File "/home/airflow/.local/lib/python3.10/site-packages/airflow/task/task_runner/standard_task_runner.py", line 117, in _start_by_fork
    ret = args.func(args, dag=self.dag)
  File "/home/airflow/.local/lib/python3.10/site-packages/airflow/cli/cli_config.py", line 49, in command
    return func(*args, **kwargs)
  File "/home/airflow/.local/lib/python3.10/site-packages/airflow/utils/cli.py", line 115, in wrapper
    return f(*args, **kwargs)
  File "/home/airflow/.local/lib/python3.10/site-packages/airflow/cli/commands/task_command.py", line 483, in task_run
    task_return_code = _run_task_by_selected_method(args, _dag, ti)
  File "/home/airflow/.local/lib/python3.10/site-packages/airflow/cli/commands/task_command.py", line 256, in _run_task_by_selected_method
    return _run_raw_task(args, ti)
  File "/home/airflow/.local/lib/python3.10/site-packages/airflow/cli/commands/task_command.py", line 341, in _run_raw_task
    return ti._run_raw_task(
  File "/home/airflow/.local/lib/python3.10/site-packages/airflow/utils/session.py", line 97, in wrapper
    return func(*args, session=session, **kwargs)
  File "/home/airflow/.local/lib/python3.10/site-packages/airflow/models/taskinstance.py", line 3004, in _run_raw_task
    return _run_raw_task(
  File "/home/airflow/.local/lib/python3.10/site-packages/airflow/models/taskinstance.py", line 273, in _run_raw_task
    TaskInstance._execute_task_with_callbacks(
  File "/home/airflow/.local/lib/python3.10/site-packages/airflow/models/taskinstance.py", line 3158, in _execute_task_with_callbacks
    result = self._execute_task(context, task_orig)
  File "/home/airflow/.local/lib/python3.10/site-packages/airflow/models/taskinstance.py", line 3182, in _execute_task
    return _execute_task(self, context, task_orig)
  File "/home/airflow/.local/lib/python3.10/site-packages/airflow/models/taskinstance.py", line 767, in _execute_task
    result = _execute_callable(context=context, **execute_callable_kwargs)
  File "/home/airflow/.local/lib/python3.10/site-packages/airflow/models/taskinstance.py", line 733, in _execute_callable
    return ExecutionCallableRunner(
  File "/home/airflow/.local/lib/python3.10/site-packages/airflow/utils/operator_helpers.py", line 252, in run
    return self.func(*args, **kwargs)
  File "/home/airflow/.local/lib/python3.10/site-packages/airflow/models/baseoperator.py", line 406, in wrapper
    return func(self, *args, **kwargs)
  File "/home/airflow/.local/lib/python3.10/site-packages/airflow/operators/bash.py", line 249, in execute
    raise AirflowException(
airflow.exceptions.AirflowException: Bash command failed. The command returned a non-zero exit code 1.
[2024-10-09T09:32:53.108+0000] {local_task_job_runner.py:266} INFO - Task exited with return code 1
[2024-10-09T09:32:53.157+0000] {taskinstance.py:3900} INFO - 0 downstream tasks scheduled from follow-on schedule check
[2024-10-09T09:32:53.168+0000] {local_task_job_runner.py:245} INFO - ::endgroup::
