[2024-10-09T09:04:13.591+0000] {local_task_job_runner.py:123} INFO - ::group::Pre task execution logs
[2024-10-09T09:04:13.621+0000] {taskinstance.py:2612} INFO - Dependencies all met for dep_context=non-requeueable deps ti=<TaskInstance: EL.extract manual__2024-10-09T09:04:12.071795+00:00 [queued]>
[2024-10-09T09:04:13.636+0000] {taskinstance.py:2612} INFO - Dependencies all met for dep_context=requeueable deps ti=<TaskInstance: EL.extract manual__2024-10-09T09:04:12.071795+00:00 [queued]>
[2024-10-09T09:04:13.637+0000] {taskinstance.py:2865} INFO - Starting attempt 1 of 1
[2024-10-09T09:04:13.665+0000] {taskinstance.py:2888} INFO - Executing <Task(BashOperator): extract> on 2024-10-09 09:04:12.071795+00:00
[2024-10-09T09:04:13.673+0000] {standard_task_runner.py:72} INFO - Started process 69 to run task
[2024-10-09T09:04:13.678+0000] {standard_task_runner.py:104} INFO - Running: ['airflow', 'tasks', 'run', 'EL', 'extract', 'manual__2024-10-09T09:04:12.071795+00:00', '--job-id', '11', '--raw', '--subdir', 'DAGS_FOLDER/scrape_dag.py', '--cfg-path', '/tmp/tmptylo9ijb']
[2024-10-09T09:04:13.682+0000] {standard_task_runner.py:105} INFO - Job 11: Subtask extract
[2024-10-09T09:04:13.700+0000] {warnings.py:109} WARNING - /home/airflow/.local/lib/python3.10/site-packages/airflow/settings.py:209: DeprecationWarning: The sql_alchemy_conn option in [core] has been moved to the sql_alchemy_conn option in [database] - the old setting has been used, but please update your config.
  SQL_ALCHEMY_CONN = conf.get("database", "SQL_ALCHEMY_CONN")

[2024-10-09T09:04:13.745+0000] {task_command.py:467} INFO - Running <TaskInstance: EL.extract manual__2024-10-09T09:04:12.071795+00:00 [running]> on host 86bc46d64177
[2024-10-09T09:04:13.918+0000] {taskinstance.py:3131} INFO - Exporting env vars: AIRFLOW_CTX_DAG_OWNER='bmw' AIRFLOW_CTX_DAG_ID='EL' AIRFLOW_CTX_TASK_ID='extract' AIRFLOW_CTX_EXECUTION_DATE='2024-10-09T09:04:12.071795+00:00' AIRFLOW_CTX_TRY_NUMBER='1' AIRFLOW_CTX_DAG_RUN_ID='manual__2024-10-09T09:04:12.071795+00:00'
[2024-10-09T09:04:13.920+0000] {taskinstance.py:731} INFO - ::endgroup::
[2024-10-09T09:04:13.948+0000] {subprocess.py:63} INFO - Tmp dir root location: /tmp
[2024-10-09T09:04:13.951+0000] {subprocess.py:75} INFO - Running command: ['/usr/bin/bash', '-c', 'xvfb-run --server-args="-screen 0 1920x1080x24" python3 /opt/airflow/scripts/scrape.py']
[2024-10-09T09:04:13.966+0000] {subprocess.py:86} INFO - Output:
[2024-10-09T09:04:17.554+0000] {subprocess.py:93} INFO - INFO:root:Opening IMDb page...
[2024-10-09T09:04:23.170+0000] {subprocess.py:93} INFO - INFO:root:Page loaded, waiting for elements...
[2024-10-09T09:04:53.348+0000] {subprocess.py:93} INFO - ERROR:root:Timeout: Element not found within the given time, saving screenshot...
[2024-10-09T09:04:53.731+0000] {subprocess.py:93} INFO - Traceback (most recent call last):
[2024-10-09T09:04:53.740+0000] {subprocess.py:93} INFO -   File "/opt/airflow/scripts/scrape.py", line 197, in <module>
[2024-10-09T09:04:53.742+0000] {subprocess.py:93} INFO -     WebDriverWait(driver, 30).until(
[2024-10-09T09:04:53.744+0000] {subprocess.py:93} INFO -   File "/home/airflow/.local/lib/python3.10/site-packages/selenium/webdriver/support/wait.py", line 105, in until
[2024-10-09T09:04:53.746+0000] {subprocess.py:93} INFO -     raise TimeoutException(message, screen, stacktrace)
[2024-10-09T09:04:53.749+0000] {subprocess.py:93} INFO - selenium.common.exceptions.TimeoutException: Message:
[2024-10-09T09:04:53.751+0000] {subprocess.py:93} INFO - Stacktrace:
[2024-10-09T09:04:53.753+0000] {subprocess.py:93} INFO - #0 0x556d1b91202a <unknown>
[2024-10-09T09:04:53.756+0000] {subprocess.py:93} INFO - #1 0x556d1b5f85e0 <unknown>
[2024-10-09T09:04:53.758+0000] {subprocess.py:93} INFO - #2 0x556d1b647be8 <unknown>
[2024-10-09T09:04:53.761+0000] {subprocess.py:93} INFO - #3 0x556d1b647e81 <unknown>
[2024-10-09T09:04:53.763+0000] {subprocess.py:93} INFO - #4 0x556d1b68e8c4 <unknown>
[2024-10-09T09:04:53.765+0000] {subprocess.py:93} INFO - #5 0x556d1b66cb4d <unknown>
[2024-10-09T09:04:53.767+0000] {subprocess.py:93} INFO - #6 0x556d1b68bd7d <unknown>
[2024-10-09T09:04:53.769+0000] {subprocess.py:93} INFO - #7 0x556d1b66c8c3 <unknown>
[2024-10-09T09:04:53.771+0000] {subprocess.py:93} INFO - #8 0x556d1b63a6b3 <unknown>
[2024-10-09T09:04:53.774+0000] {subprocess.py:93} INFO - #9 0x556d1b63b68e <unknown>
[2024-10-09T09:04:53.776+0000] {subprocess.py:93} INFO - #10 0x556d1b8dca2b <unknown>
[2024-10-09T09:04:53.778+0000] {subprocess.py:93} INFO - #11 0x556d1b8e09b1 <unknown>
[2024-10-09T09:04:53.780+0000] {subprocess.py:93} INFO - #12 0x556d1b8c9225 <unknown>
[2024-10-09T09:04:53.782+0000] {subprocess.py:93} INFO - #13 0x556d1b8e1532 <unknown>
[2024-10-09T09:04:53.785+0000] {subprocess.py:93} INFO - #14 0x556d1b8ae38f <unknown>
[2024-10-09T09:04:53.787+0000] {subprocess.py:93} INFO - #15 0x556d1b900f28 <unknown>
[2024-10-09T09:04:53.789+0000] {subprocess.py:93} INFO - #16 0x556d1b9010f3 <unknown>
[2024-10-09T09:04:53.791+0000] {subprocess.py:93} INFO - #17 0x556d1b910e7c <unknown>
[2024-10-09T09:04:53.794+0000] {subprocess.py:93} INFO - #18 0x7f3922fb8144 <unknown>
[2024-10-09T09:04:53.796+0000] {subprocess.py:93} INFO - 
[2024-10-09T09:04:53.954+0000] {subprocess.py:97} INFO - Command exited with return code 1
[2024-10-09T09:04:53.980+0000] {taskinstance.py:3310} ERROR - Task failed with exception
Traceback (most recent call last):
  File "/home/airflow/.local/lib/python3.10/site-packages/airflow/models/taskinstance.py", line 767, in _execute_task
    result = _execute_callable(context=context, **execute_callable_kwargs)
  File "/home/airflow/.local/lib/python3.10/site-packages/airflow/models/taskinstance.py", line 733, in _execute_callable
    return ExecutionCallableRunner(
  File "/home/airflow/.local/lib/python3.10/site-packages/airflow/utils/operator_helpers.py", line 252, in run
    return self.func(*args, **kwargs)
  File "/home/airflow/.local/lib/python3.10/site-packages/airflow/models/baseoperator.py", line 406, in wrapper
    return func(self, *args, **kwargs)
  File "/home/airflow/.local/lib/python3.10/site-packages/airflow/operators/bash.py", line 249, in execute
    raise AirflowException(
airflow.exceptions.AirflowException: Bash command failed. The command returned a non-zero exit code 1.
[2024-10-09T09:04:53.993+0000] {taskinstance.py:1225} INFO - Marking task as FAILED. dag_id=EL, task_id=extract, run_id=manual__2024-10-09T09:04:12.071795+00:00, execution_date=20241009T090412, start_date=20241009T090413, end_date=20241009T090453
[2024-10-09T09:04:54.026+0000] {taskinstance.py:340} INFO - ::group::Post task execution logs
[2024-10-09T09:04:54.029+0000] {standard_task_runner.py:124} ERROR - Failed to execute job 11 for task extract (Bash command failed. The command returned a non-zero exit code 1.; 69)
Traceback (most recent call last):
  File "/home/airflow/.local/lib/python3.10/site-packages/airflow/task/task_runner/standard_task_runner.py", line 117, in _start_by_fork
    ret = args.func(args, dag=self.dag)
  File "/home/airflow/.local/lib/python3.10/site-packages/airflow/cli/cli_config.py", line 49, in command
    return func(*args, **kwargs)
  File "/home/airflow/.local/lib/python3.10/site-packages/airflow/utils/cli.py", line 115, in wrapper
    return f(*args, **kwargs)
  File "/home/airflow/.local/lib/python3.10/site-packages/airflow/cli/commands/task_command.py", line 483, in task_run
    task_return_code = _run_task_by_selected_method(args, _dag, ti)
  File "/home/airflow/.local/lib/python3.10/site-packages/airflow/cli/commands/task_command.py", line 256, in _run_task_by_selected_method
    return _run_raw_task(args, ti)
  File "/home/airflow/.local/lib/python3.10/site-packages/airflow/cli/commands/task_command.py", line 341, in _run_raw_task
    return ti._run_raw_task(
  File "/home/airflow/.local/lib/python3.10/site-packages/airflow/utils/session.py", line 97, in wrapper
    return func(*args, session=session, **kwargs)
  File "/home/airflow/.local/lib/python3.10/site-packages/airflow/models/taskinstance.py", line 3004, in _run_raw_task
    return _run_raw_task(
  File "/home/airflow/.local/lib/python3.10/site-packages/airflow/models/taskinstance.py", line 273, in _run_raw_task
    TaskInstance._execute_task_with_callbacks(
  File "/home/airflow/.local/lib/python3.10/site-packages/airflow/models/taskinstance.py", line 3158, in _execute_task_with_callbacks
    result = self._execute_task(context, task_orig)
  File "/home/airflow/.local/lib/python3.10/site-packages/airflow/models/taskinstance.py", line 3182, in _execute_task
    return _execute_task(self, context, task_orig)
  File "/home/airflow/.local/lib/python3.10/site-packages/airflow/models/taskinstance.py", line 767, in _execute_task
    result = _execute_callable(context=context, **execute_callable_kwargs)
  File "/home/airflow/.local/lib/python3.10/site-packages/airflow/models/taskinstance.py", line 733, in _execute_callable
    return ExecutionCallableRunner(
  File "/home/airflow/.local/lib/python3.10/site-packages/airflow/utils/operator_helpers.py", line 252, in run
    return self.func(*args, **kwargs)
  File "/home/airflow/.local/lib/python3.10/site-packages/airflow/models/baseoperator.py", line 406, in wrapper
    return func(self, *args, **kwargs)
  File "/home/airflow/.local/lib/python3.10/site-packages/airflow/operators/bash.py", line 249, in execute
    raise AirflowException(
airflow.exceptions.AirflowException: Bash command failed. The command returned a non-zero exit code 1.
[2024-10-09T09:04:54.088+0000] {local_task_job_runner.py:266} INFO - Task exited with return code 1
[2024-10-09T09:04:54.133+0000] {taskinstance.py:3900} INFO - 0 downstream tasks scheduled from follow-on schedule check
[2024-10-09T09:04:54.144+0000] {local_task_job_runner.py:245} INFO - ::endgroup::
